[2023-11-20T22:19:30.003+0000] {taskinstance.py:1159} INFO - Dependencies all met for dep_context=non-requeueable deps ti=<TaskInstance: outcomes_dag.load_animals_dim scheduled__2023-11-02T00:00:00+00:00 [queued]>
[2023-11-20T22:19:30.009+0000] {taskinstance.py:1159} INFO - Dependencies all met for dep_context=requeueable deps ti=<TaskInstance: outcomes_dag.load_animals_dim scheduled__2023-11-02T00:00:00+00:00 [queued]>
[2023-11-20T22:19:30.010+0000] {taskinstance.py:1361} INFO - Starting attempt 1 of 1
[2023-11-20T22:19:30.017+0000] {taskinstance.py:1382} INFO - Executing <Task(PythonOperator): load_animals_dim> on 2023-11-02 00:00:00+00:00
[2023-11-20T22:19:30.023+0000] {standard_task_runner.py:57} INFO - Started process 270 to run task
[2023-11-20T22:19:30.028+0000] {standard_task_runner.py:84} INFO - Running: ['***', 'tasks', 'run', 'outcomes_dag', 'load_animals_dim', 'scheduled__2023-11-02T00:00:00+00:00', '--job-id', '38', '--raw', '--subdir', 'DAGS_FOLDER/outcomes_dag.py', '--cfg-path', '/tmp/tmpzo6ep7xr']
[2023-11-20T22:19:30.031+0000] {standard_task_runner.py:85} INFO - Job 38: Subtask load_animals_dim
[2023-11-20T22:19:30.067+0000] {task_command.py:416} INFO - Running <TaskInstance: outcomes_dag.load_animals_dim scheduled__2023-11-02T00:00:00+00:00 [running]> on host 3286f6d7d5f2
[2023-11-20T22:19:30.418+0000] {taskinstance.py:1662} INFO - Exporting env vars: AIRFLOW_CTX_DAG_OWNER='***' AIRFLOW_CTX_DAG_ID='outcomes_dag' AIRFLOW_CTX_TASK_ID='load_animals_dim' AIRFLOW_CTX_EXECUTION_DATE='2023-11-02T00:00:00+00:00' AIRFLOW_CTX_TRY_NUMBER='1' AIRFLOW_CTX_DAG_RUN_ID='scheduled__2023-11-02T00:00:00+00:00'
[2023-11-20T22:19:30.420+0000] {taskinstance.py:1937} ERROR - Task failed with exception
Traceback (most recent call last):
  File "/home/airflow/.local/lib/python3.8/site-packages/airflow/operators/python.py", line 192, in execute
    return_value = self.execute_callable()
  File "/home/airflow/.local/lib/python3.8/site-packages/airflow/operators/python.py", line 209, in execute_callable
    return self.python_callable(*self.op_args, **self.op_kwargs)
  File "/opt/airflow/dags/etl_scripts/load.py", line 12, in load_data
    db_url = os.environ['DB_URL']
  File "/usr/local/lib/python3.8/os.py", line 675, in __getitem__
    raise KeyError(key) from None
KeyError: 'DB_URL'
[2023-11-20T22:19:30.429+0000] {taskinstance.py:1400} INFO - Marking task as FAILED. dag_id=outcomes_dag, task_id=load_animals_dim, execution_date=20231102T000000, start_date=20231120T221930, end_date=20231120T221930
[2023-11-20T22:19:30.436+0000] {standard_task_runner.py:104} ERROR - Failed to execute job 38 for task load_animals_dim ('DB_URL'; 270)
[2023-11-20T22:19:30.449+0000] {local_task_job_runner.py:228} INFO - Task exited with return code 1
[2023-11-20T22:19:30.462+0000] {taskinstance.py:2778} INFO - 0 downstream tasks scheduled from follow-on schedule check
