[2023-11-20T23:58:22.399+0000] {taskinstance.py:1159} INFO - Dependencies all met for dep_context=non-requeueable deps ti=<TaskInstance: outcomes_dag.load_outcome_types_dim scheduled__2023-11-18T00:00:00+00:00 [queued]>
[2023-11-20T23:58:22.413+0000] {taskinstance.py:1159} INFO - Dependencies all met for dep_context=requeueable deps ti=<TaskInstance: outcomes_dag.load_outcome_types_dim scheduled__2023-11-18T00:00:00+00:00 [queued]>
[2023-11-20T23:58:22.415+0000] {taskinstance.py:1361} INFO - Starting attempt 1 of 1
[2023-11-20T23:58:22.436+0000] {taskinstance.py:1382} INFO - Executing <Task(PythonOperator): load_outcome_types_dim> on 2023-11-18 00:00:00+00:00
[2023-11-20T23:58:22.451+0000] {standard_task_runner.py:57} INFO - Started process 328 to run task
[2023-11-20T23:58:22.455+0000] {standard_task_runner.py:84} INFO - Running: ['***', 'tasks', 'run', 'outcomes_dag', 'load_outcome_types_dim', 'scheduled__2023-11-18T00:00:00+00:00', '--job-id', '40', '--raw', '--subdir', 'DAGS_FOLDER/outcomes_dag.py', '--cfg-path', '/tmp/tmpp6c3a1ul']
[2023-11-20T23:58:22.460+0000] {standard_task_runner.py:85} INFO - Job 40: Subtask load_outcome_types_dim
[2023-11-20T23:58:22.534+0000] {task_command.py:416} INFO - Running <TaskInstance: outcomes_dag.load_outcome_types_dim scheduled__2023-11-18T00:00:00+00:00 [running]> on host 3aa39f73e581
[2023-11-20T23:58:23.683+0000] {taskinstance.py:1662} INFO - Exporting env vars: AIRFLOW_CTX_DAG_OWNER='***' AIRFLOW_CTX_DAG_ID='outcomes_dag' AIRFLOW_CTX_TASK_ID='load_outcome_types_dim' AIRFLOW_CTX_EXECUTION_DATE='2023-11-18T00:00:00+00:00' AIRFLOW_CTX_TRY_NUMBER='1' AIRFLOW_CTX_DAG_RUN_ID='scheduled__2023-11-18T00:00:00+00:00'
[2023-11-20T23:58:23.900+0000] {taskinstance.py:1937} ERROR - Task failed with exception
Traceback (most recent call last):
  File "/home/airflow/.local/lib/python3.8/site-packages/sqlalchemy/engine/base.py", line 1890, in _execute_context
    self.dialect.do_executemany(
  File "/home/airflow/.local/lib/python3.8/site-packages/sqlalchemy/dialects/postgresql/psycopg2.py", line 982, in do_executemany
    context._psycopg2_fetched_rows = xtras.execute_values(
  File "/home/airflow/.local/lib/python3.8/site-packages/psycopg2/extras.py", line 1299, in execute_values
    cur.execute(b''.join(parts))
psycopg2.errors.UniqueViolation: duplicate key value violates unique constraint "dim_outcome_types_pkey"
DETAIL:  Key (outcome_type_id)=(1) already exists.


The above exception was the direct cause of the following exception:

Traceback (most recent call last):
  File "/home/airflow/.local/lib/python3.8/site-packages/airflow/operators/python.py", line 192, in execute
    return_value = self.execute_callable()
  File "/home/airflow/.local/lib/python3.8/site-packages/airflow/operators/python.py", line 209, in execute_callable
    return self.python_callable(*self.op_args, **self.op_kwargs)
  File "/opt/airflow/dags/etl_scripts/load.py", line 20, in load_data
    pd.read_parquet(table_file).to_sql(table_name, conn, if_exists="append", index=False)
  File "/home/airflow/.local/lib/python3.8/site-packages/pandas/core/generic.py", line 2878, in to_sql
    return sql.to_sql(
  File "/home/airflow/.local/lib/python3.8/site-packages/pandas/io/sql.py", line 769, in to_sql
    return pandas_sql.to_sql(
  File "/home/airflow/.local/lib/python3.8/site-packages/pandas/io/sql.py", line 1920, in to_sql
    total_inserted = sql_engine.insert_records(
  File "/home/airflow/.local/lib/python3.8/site-packages/pandas/io/sql.py", line 1470, in insert_records
    raise err
  File "/home/airflow/.local/lib/python3.8/site-packages/pandas/io/sql.py", line 1461, in insert_records
    return table.insert(chunksize=chunksize, method=method)
  File "/home/airflow/.local/lib/python3.8/site-packages/pandas/io/sql.py", line 1023, in insert
    num_inserted = exec_insert(conn, keys, chunk_iter)
  File "/home/airflow/.local/lib/python3.8/site-packages/pandas/io/sql.py", line 929, in _execute_insert
    result = conn.execute(self.table.insert(), data)
  File "/home/airflow/.local/lib/python3.8/site-packages/sqlalchemy/engine/base.py", line 1385, in execute
    return meth(self, multiparams, params, _EMPTY_EXECUTION_OPTS)
  File "/home/airflow/.local/lib/python3.8/site-packages/sqlalchemy/sql/elements.py", line 334, in _execute_on_connection
    return connection._execute_clauseelement(
  File "/home/airflow/.local/lib/python3.8/site-packages/sqlalchemy/engine/base.py", line 1577, in _execute_clauseelement
    ret = self._execute_context(
  File "/home/airflow/.local/lib/python3.8/site-packages/sqlalchemy/engine/base.py", line 1953, in _execute_context
    self._handle_dbapi_exception(
  File "/home/airflow/.local/lib/python3.8/site-packages/sqlalchemy/engine/base.py", line 2134, in _handle_dbapi_exception
    util.raise_(
  File "/home/airflow/.local/lib/python3.8/site-packages/sqlalchemy/util/compat.py", line 211, in raise_
    raise exception
  File "/home/airflow/.local/lib/python3.8/site-packages/sqlalchemy/engine/base.py", line 1890, in _execute_context
    self.dialect.do_executemany(
  File "/home/airflow/.local/lib/python3.8/site-packages/sqlalchemy/dialects/postgresql/psycopg2.py", line 982, in do_executemany
    context._psycopg2_fetched_rows = xtras.execute_values(
  File "/home/airflow/.local/lib/python3.8/site-packages/psycopg2/extras.py", line 1299, in execute_values
    cur.execute(b''.join(parts))
sqlalchemy.exc.IntegrityError: (psycopg2.errors.UniqueViolation) duplicate key value violates unique constraint "dim_outcome_types_pkey"
DETAIL:  Key (outcome_type_id)=(1) already exists.

[SQL: INSERT INTO dim_outcome_types (outcome_type, outcome_type_id) VALUES (%(outcome_type)s, %(outcome_type_id)s)]
[parameters: ({'outcome_type': 'Rto-Adopt', 'outcome_type_id': 1}, {'outcome_type': 'Adoption', 'outcome_type_id': 2}, {'outcome_type': 'Euthanasia', 'outcome_type_id': 3}, {'outcome_type': 'Transfer', 'outcome_type_id': 4}, {'outcome_type': 'Return to Owner', 'outcome_type_id': 5}, {'outcome_type': 'Died', 'outcome_type_id': 6}, {'outcome_type': 'Disposal', 'outcome_type_id': 7}, {'outcome_type': 'Missing', 'outcome_type_id': 8}  ... displaying 10 of 11 total bound parameter sets ...  {'outcome_type': 'N/A', 'outcome_type_id': 10}, {'outcome_type': 'Stolen', 'outcome_type_id': 11})]
(Background on this error at: https://sqlalche.me/e/14/gkpj)
[2023-11-20T23:58:23.925+0000] {taskinstance.py:1400} INFO - Marking task as FAILED. dag_id=outcomes_dag, task_id=load_outcome_types_dim, execution_date=20231118T000000, start_date=20231120T235822, end_date=20231120T235823
[2023-11-20T23:58:23.948+0000] {standard_task_runner.py:104} ERROR - Failed to execute job 40 for task load_outcome_types_dim ((psycopg2.errors.UniqueViolation) duplicate key value violates unique constraint "dim_outcome_types_pkey"
DETAIL:  Key (outcome_type_id)=(1) already exists.

[SQL: INSERT INTO dim_outcome_types (outcome_type, outcome_type_id) VALUES (%(outcome_type)s, %(outcome_type_id)s)]
[parameters: ({'outcome_type': 'Rto-Adopt', 'outcome_type_id': 1}, {'outcome_type': 'Adoption', 'outcome_type_id': 2}, {'outcome_type': 'Euthanasia', 'outcome_type_id': 3}, {'outcome_type': 'Transfer', 'outcome_type_id': 4}, {'outcome_type': 'Return to Owner', 'outcome_type_id': 5}, {'outcome_type': 'Died', 'outcome_type_id': 6}, {'outcome_type': 'Disposal', 'outcome_type_id': 7}, {'outcome_type': 'Missing', 'outcome_type_id': 8}  ... displaying 10 of 11 total bound parameter sets ...  {'outcome_type': 'N/A', 'outcome_type_id': 10}, {'outcome_type': 'Stolen', 'outcome_type_id': 11})]
(Background on this error at: https://sqlalche.me/e/14/gkpj); 328)
[2023-11-20T23:58:23.997+0000] {local_task_job_runner.py:228} INFO - Task exited with return code 1
[2023-11-20T23:58:24.076+0000] {taskinstance.py:2778} INFO - 0 downstream tasks scheduled from follow-on schedule check
[2023-11-21T03:57:21.315+0000] {taskinstance.py:1159} INFO - Dependencies all met for dep_context=non-requeueable deps ti=<TaskInstance: outcomes_dag.load_outcome_types_dim scheduled__2023-11-18T00:00:00+00:00 [queued]>
[2023-11-21T03:57:21.333+0000] {taskinstance.py:1159} INFO - Dependencies all met for dep_context=requeueable deps ti=<TaskInstance: outcomes_dag.load_outcome_types_dim scheduled__2023-11-18T00:00:00+00:00 [queued]>
[2023-11-21T03:57:21.334+0000] {taskinstance.py:1361} INFO - Starting attempt 1 of 1
[2023-11-21T03:57:21.357+0000] {taskinstance.py:1382} INFO - Executing <Task(PythonOperator): load_outcome_types_dim> on 2023-11-18 00:00:00+00:00
[2023-11-21T03:57:21.392+0000] {standard_task_runner.py:57} INFO - Started process 774 to run task
[2023-11-21T03:57:21.412+0000] {standard_task_runner.py:84} INFO - Running: ['***', 'tasks', 'run', 'outcomes_dag', 'load_outcome_types_dim', 'scheduled__2023-11-18T00:00:00+00:00', '--job-id', '51', '--raw', '--subdir', 'DAGS_FOLDER/outcomes_dag.py', '--cfg-path', '/tmp/tmptyh822vu']
[2023-11-21T03:57:21.421+0000] {standard_task_runner.py:85} INFO - Job 51: Subtask load_outcome_types_dim
[2023-11-21T03:57:21.699+0000] {task_command.py:416} INFO - Running <TaskInstance: outcomes_dag.load_outcome_types_dim scheduled__2023-11-18T00:00:00+00:00 [running]> on host a0f615083db8
[2023-11-21T03:57:23.326+0000] {taskinstance.py:1662} INFO - Exporting env vars: AIRFLOW_CTX_DAG_OWNER='***' AIRFLOW_CTX_DAG_ID='outcomes_dag' AIRFLOW_CTX_TASK_ID='load_outcome_types_dim' AIRFLOW_CTX_EXECUTION_DATE='2023-11-18T00:00:00+00:00' AIRFLOW_CTX_TRY_NUMBER='1' AIRFLOW_CTX_DAG_RUN_ID='scheduled__2023-11-18T00:00:00+00:00'
[2023-11-21T03:57:23.643+0000] {taskinstance.py:1937} ERROR - Task failed with exception
Traceback (most recent call last):
  File "/home/airflow/.local/lib/python3.8/site-packages/sqlalchemy/engine/base.py", line 1890, in _execute_context
    self.dialect.do_executemany(
  File "/home/airflow/.local/lib/python3.8/site-packages/sqlalchemy/dialects/postgresql/psycopg2.py", line 982, in do_executemany
    context._psycopg2_fetched_rows = xtras.execute_values(
  File "/home/airflow/.local/lib/python3.8/site-packages/psycopg2/extras.py", line 1299, in execute_values
    cur.execute(b''.join(parts))
psycopg2.errors.UniqueViolation: duplicate key value violates unique constraint "dim_outcome_types_pkey"
DETAIL:  Key (outcome_type_id)=(1) already exists.


The above exception was the direct cause of the following exception:

Traceback (most recent call last):
  File "/home/airflow/.local/lib/python3.8/site-packages/airflow/operators/python.py", line 192, in execute
    return_value = self.execute_callable()
  File "/home/airflow/.local/lib/python3.8/site-packages/airflow/operators/python.py", line 209, in execute_callable
    return self.python_callable(*self.op_args, **self.op_kwargs)
  File "/opt/airflow/dags/etl_scripts/load.py", line 20, in load_data
    pd.read_parquet(table_file).to_sql(table_name, conn, if_exists="append", index=False)
  File "/home/airflow/.local/lib/python3.8/site-packages/pandas/core/generic.py", line 2878, in to_sql
    return sql.to_sql(
  File "/home/airflow/.local/lib/python3.8/site-packages/pandas/io/sql.py", line 769, in to_sql
    return pandas_sql.to_sql(
  File "/home/airflow/.local/lib/python3.8/site-packages/pandas/io/sql.py", line 1920, in to_sql
    total_inserted = sql_engine.insert_records(
  File "/home/airflow/.local/lib/python3.8/site-packages/pandas/io/sql.py", line 1470, in insert_records
    raise err
  File "/home/airflow/.local/lib/python3.8/site-packages/pandas/io/sql.py", line 1461, in insert_records
    return table.insert(chunksize=chunksize, method=method)
  File "/home/airflow/.local/lib/python3.8/site-packages/pandas/io/sql.py", line 1023, in insert
    num_inserted = exec_insert(conn, keys, chunk_iter)
  File "/home/airflow/.local/lib/python3.8/site-packages/pandas/io/sql.py", line 929, in _execute_insert
    result = conn.execute(self.table.insert(), data)
  File "/home/airflow/.local/lib/python3.8/site-packages/sqlalchemy/engine/base.py", line 1385, in execute
    return meth(self, multiparams, params, _EMPTY_EXECUTION_OPTS)
  File "/home/airflow/.local/lib/python3.8/site-packages/sqlalchemy/sql/elements.py", line 334, in _execute_on_connection
    return connection._execute_clauseelement(
  File "/home/airflow/.local/lib/python3.8/site-packages/sqlalchemy/engine/base.py", line 1577, in _execute_clauseelement
    ret = self._execute_context(
  File "/home/airflow/.local/lib/python3.8/site-packages/sqlalchemy/engine/base.py", line 1953, in _execute_context
    self._handle_dbapi_exception(
  File "/home/airflow/.local/lib/python3.8/site-packages/sqlalchemy/engine/base.py", line 2134, in _handle_dbapi_exception
    util.raise_(
  File "/home/airflow/.local/lib/python3.8/site-packages/sqlalchemy/util/compat.py", line 211, in raise_
    raise exception
  File "/home/airflow/.local/lib/python3.8/site-packages/sqlalchemy/engine/base.py", line 1890, in _execute_context
    self.dialect.do_executemany(
  File "/home/airflow/.local/lib/python3.8/site-packages/sqlalchemy/dialects/postgresql/psycopg2.py", line 982, in do_executemany
    context._psycopg2_fetched_rows = xtras.execute_values(
  File "/home/airflow/.local/lib/python3.8/site-packages/psycopg2/extras.py", line 1299, in execute_values
    cur.execute(b''.join(parts))
sqlalchemy.exc.IntegrityError: (psycopg2.errors.UniqueViolation) duplicate key value violates unique constraint "dim_outcome_types_pkey"
DETAIL:  Key (outcome_type_id)=(1) already exists.

[SQL: INSERT INTO dim_outcome_types (outcome_type, outcome_type_id) VALUES (%(outcome_type)s, %(outcome_type_id)s)]
[parameters: ({'outcome_type': 'Rto-Adopt', 'outcome_type_id': 1}, {'outcome_type': 'Adoption', 'outcome_type_id': 2}, {'outcome_type': 'Euthanasia', 'outcome_type_id': 3}, {'outcome_type': 'Transfer', 'outcome_type_id': 4}, {'outcome_type': 'Return to Owner', 'outcome_type_id': 5}, {'outcome_type': 'Died', 'outcome_type_id': 6}, {'outcome_type': 'Disposal', 'outcome_type_id': 7}, {'outcome_type': 'Missing', 'outcome_type_id': 8}  ... displaying 10 of 11 total bound parameter sets ...  {'outcome_type': 'N/A', 'outcome_type_id': 10}, {'outcome_type': 'Stolen', 'outcome_type_id': 11})]
(Background on this error at: https://sqlalche.me/e/14/gkpj)
[2023-11-21T03:57:23.749+0000] {taskinstance.py:1400} INFO - Marking task as FAILED. dag_id=outcomes_dag, task_id=load_outcome_types_dim, execution_date=20231118T000000, start_date=20231121T035721, end_date=20231121T035723
[2023-11-21T03:57:23.861+0000] {standard_task_runner.py:104} ERROR - Failed to execute job 51 for task load_outcome_types_dim ((psycopg2.errors.UniqueViolation) duplicate key value violates unique constraint "dim_outcome_types_pkey"
DETAIL:  Key (outcome_type_id)=(1) already exists.

[SQL: INSERT INTO dim_outcome_types (outcome_type, outcome_type_id) VALUES (%(outcome_type)s, %(outcome_type_id)s)]
[parameters: ({'outcome_type': 'Rto-Adopt', 'outcome_type_id': 1}, {'outcome_type': 'Adoption', 'outcome_type_id': 2}, {'outcome_type': 'Euthanasia', 'outcome_type_id': 3}, {'outcome_type': 'Transfer', 'outcome_type_id': 4}, {'outcome_type': 'Return to Owner', 'outcome_type_id': 5}, {'outcome_type': 'Died', 'outcome_type_id': 6}, {'outcome_type': 'Disposal', 'outcome_type_id': 7}, {'outcome_type': 'Missing', 'outcome_type_id': 8}  ... displaying 10 of 11 total bound parameter sets ...  {'outcome_type': 'N/A', 'outcome_type_id': 10}, {'outcome_type': 'Stolen', 'outcome_type_id': 11})]
(Background on this error at: https://sqlalche.me/e/14/gkpj); 774)
[2023-11-21T03:57:24.010+0000] {local_task_job_runner.py:228} INFO - Task exited with return code 1
[2023-11-21T03:57:24.139+0000] {taskinstance.py:2778} INFO - 0 downstream tasks scheduled from follow-on schedule check
[2023-11-21T04:17:56.096+0000] {taskinstance.py:1159} INFO - Dependencies all met for dep_context=non-requeueable deps ti=<TaskInstance: outcomes_dag.load_outcome_types_dim scheduled__2023-11-18T00:00:00+00:00 [queued]>
[2023-11-21T04:17:56.571+0000] {taskinstance.py:1159} INFO - Dependencies all met for dep_context=requeueable deps ti=<TaskInstance: outcomes_dag.load_outcome_types_dim scheduled__2023-11-18T00:00:00+00:00 [queued]>
[2023-11-21T04:17:56.584+0000] {taskinstance.py:1361} INFO - Starting attempt 1 of 1
[2023-11-21T04:17:56.701+0000] {taskinstance.py:1382} INFO - Executing <Task(PythonOperator): load_outcome_types_dim> on 2023-11-18 00:00:00+00:00
[2023-11-21T04:17:56.782+0000] {standard_task_runner.py:57} INFO - Started process 399 to run task
[2023-11-21T04:17:56.821+0000] {standard_task_runner.py:84} INFO - Running: ['***', 'tasks', 'run', 'outcomes_dag', 'load_outcome_types_dim', 'scheduled__2023-11-18T00:00:00+00:00', '--job-id', '46', '--raw', '--subdir', 'DAGS_FOLDER/outcomes_dag.py', '--cfg-path', '/tmp/tmpkxrlooel']
[2023-11-21T04:17:56.841+0000] {standard_task_runner.py:85} INFO - Job 46: Subtask load_outcome_types_dim
[2023-11-21T04:17:57.414+0000] {task_command.py:416} INFO - Running <TaskInstance: outcomes_dag.load_outcome_types_dim scheduled__2023-11-18T00:00:00+00:00 [running]> on host dc3ce06c67c1
[2023-11-21T04:18:19.048+0000] {taskinstance.py:1662} INFO - Exporting env vars: AIRFLOW_CTX_DAG_OWNER='***' AIRFLOW_CTX_DAG_ID='outcomes_dag' AIRFLOW_CTX_TASK_ID='load_outcome_types_dim' AIRFLOW_CTX_EXECUTION_DATE='2023-11-18T00:00:00+00:00' AIRFLOW_CTX_TRY_NUMBER='1' AIRFLOW_CTX_DAG_RUN_ID='scheduled__2023-11-18T00:00:00+00:00'
[2023-11-21T04:18:22.507+0000] {taskinstance.py:1937} ERROR - Task failed with exception
Traceback (most recent call last):
  File "/home/airflow/.local/lib/python3.8/site-packages/sqlalchemy/engine/base.py", line 3371, in _wrap_pool_connect
    return fn()
  File "/home/airflow/.local/lib/python3.8/site-packages/sqlalchemy/pool/base.py", line 327, in connect
    return _ConnectionFairy._checkout(self)
  File "/home/airflow/.local/lib/python3.8/site-packages/sqlalchemy/pool/base.py", line 894, in _checkout
    fairy = _ConnectionRecord.checkout(pool)
  File "/home/airflow/.local/lib/python3.8/site-packages/sqlalchemy/pool/base.py", line 493, in checkout
    rec = pool._do_get()
  File "/home/airflow/.local/lib/python3.8/site-packages/sqlalchemy/pool/impl.py", line 146, in _do_get
    self._dec_overflow()
  File "/home/airflow/.local/lib/python3.8/site-packages/sqlalchemy/util/langhelpers.py", line 70, in __exit__
    compat.raise_(
  File "/home/airflow/.local/lib/python3.8/site-packages/sqlalchemy/util/compat.py", line 211, in raise_
    raise exception
  File "/home/airflow/.local/lib/python3.8/site-packages/sqlalchemy/pool/impl.py", line 143, in _do_get
    return self._create_connection()
  File "/home/airflow/.local/lib/python3.8/site-packages/sqlalchemy/pool/base.py", line 273, in _create_connection
    return _ConnectionRecord(self)
  File "/home/airflow/.local/lib/python3.8/site-packages/sqlalchemy/pool/base.py", line 388, in __init__
    self.__connect()
  File "/home/airflow/.local/lib/python3.8/site-packages/sqlalchemy/pool/base.py", line 691, in __connect
    pool.logger.debug("Error on connect(): %s", e)
  File "/home/airflow/.local/lib/python3.8/site-packages/sqlalchemy/util/langhelpers.py", line 70, in __exit__
    compat.raise_(
  File "/home/airflow/.local/lib/python3.8/site-packages/sqlalchemy/util/compat.py", line 211, in raise_
    raise exception
  File "/home/airflow/.local/lib/python3.8/site-packages/sqlalchemy/pool/base.py", line 686, in __connect
    self.dbapi_connection = connection = pool._invoke_creator(self)
  File "/home/airflow/.local/lib/python3.8/site-packages/sqlalchemy/engine/create.py", line 574, in connect
    return dialect.connect(*cargs, **cparams)
  File "/home/airflow/.local/lib/python3.8/site-packages/sqlalchemy/engine/default.py", line 598, in connect
    return self.dbapi.connect(*cargs, **cparams)
  File "/home/airflow/.local/lib/python3.8/site-packages/psycopg2/__init__.py", line 122, in connect
    conn = _connect(dsn, connection_factory=connection_factory, **kwasync)
psycopg2.OperationalError: could not translate host name "database" to address: Name or service not known


The above exception was the direct cause of the following exception:

Traceback (most recent call last):
  File "/home/airflow/.local/lib/python3.8/site-packages/airflow/operators/python.py", line 192, in execute
    return_value = self.execute_callable()
  File "/home/airflow/.local/lib/python3.8/site-packages/airflow/operators/python.py", line 209, in execute_callable
    return self.python_callable(*self.op_args, **self.op_kwargs)
  File "/opt/airflow/dags/etl_scripts/load.py", line 20, in load_data
    pd.read_parquet(table_file).to_sql(table_name, conn, if_exists="append", index=False, method = insert_on_conflict_nothing)
  File "/home/airflow/.local/lib/python3.8/site-packages/pandas/core/generic.py", line 2878, in to_sql
    return sql.to_sql(
  File "/home/airflow/.local/lib/python3.8/site-packages/pandas/io/sql.py", line 768, in to_sql
    with pandasSQL_builder(con, schema=schema, need_transaction=True) as pandas_sql:
  File "/home/airflow/.local/lib/python3.8/site-packages/pandas/io/sql.py", line 832, in pandasSQL_builder
    return SQLDatabase(con, schema, need_transaction)
  File "/home/airflow/.local/lib/python3.8/site-packages/pandas/io/sql.py", line 1539, in __init__
    con = self.exit_stack.enter_context(con.connect())
  File "/home/airflow/.local/lib/python3.8/site-packages/sqlalchemy/engine/base.py", line 3325, in connect
    return self._connection_cls(self, close_with_result=close_with_result)
  File "/home/airflow/.local/lib/python3.8/site-packages/sqlalchemy/engine/base.py", line 96, in __init__
    else engine.raw_connection()
  File "/home/airflow/.local/lib/python3.8/site-packages/sqlalchemy/engine/base.py", line 3404, in raw_connection
    return self._wrap_pool_connect(self.pool.connect, _connection)
  File "/home/airflow/.local/lib/python3.8/site-packages/sqlalchemy/engine/base.py", line 3374, in _wrap_pool_connect
    Connection._handle_dbapi_exception_noconnection(
  File "/home/airflow/.local/lib/python3.8/site-packages/sqlalchemy/engine/base.py", line 2208, in _handle_dbapi_exception_noconnection
    util.raise_(
  File "/home/airflow/.local/lib/python3.8/site-packages/sqlalchemy/util/compat.py", line 211, in raise_
    raise exception
  File "/home/airflow/.local/lib/python3.8/site-packages/sqlalchemy/engine/base.py", line 3371, in _wrap_pool_connect
    return fn()
  File "/home/airflow/.local/lib/python3.8/site-packages/sqlalchemy/pool/base.py", line 327, in connect
    return _ConnectionFairy._checkout(self)
  File "/home/airflow/.local/lib/python3.8/site-packages/sqlalchemy/pool/base.py", line 894, in _checkout
    fairy = _ConnectionRecord.checkout(pool)
  File "/home/airflow/.local/lib/python3.8/site-packages/sqlalchemy/pool/base.py", line 493, in checkout
    rec = pool._do_get()
  File "/home/airflow/.local/lib/python3.8/site-packages/sqlalchemy/pool/impl.py", line 146, in _do_get
    self._dec_overflow()
  File "/home/airflow/.local/lib/python3.8/site-packages/sqlalchemy/util/langhelpers.py", line 70, in __exit__
    compat.raise_(
  File "/home/airflow/.local/lib/python3.8/site-packages/sqlalchemy/util/compat.py", line 211, in raise_
    raise exception
  File "/home/airflow/.local/lib/python3.8/site-packages/sqlalchemy/pool/impl.py", line 143, in _do_get
    return self._create_connection()
  File "/home/airflow/.local/lib/python3.8/site-packages/sqlalchemy/pool/base.py", line 273, in _create_connection
    return _ConnectionRecord(self)
  File "/home/airflow/.local/lib/python3.8/site-packages/sqlalchemy/pool/base.py", line 388, in __init__
    self.__connect()
  File "/home/airflow/.local/lib/python3.8/site-packages/sqlalchemy/pool/base.py", line 691, in __connect
    pool.logger.debug("Error on connect(): %s", e)
  File "/home/airflow/.local/lib/python3.8/site-packages/sqlalchemy/util/langhelpers.py", line 70, in __exit__
    compat.raise_(
  File "/home/airflow/.local/lib/python3.8/site-packages/sqlalchemy/util/compat.py", line 211, in raise_
    raise exception
  File "/home/airflow/.local/lib/python3.8/site-packages/sqlalchemy/pool/base.py", line 686, in __connect
    self.dbapi_connection = connection = pool._invoke_creator(self)
  File "/home/airflow/.local/lib/python3.8/site-packages/sqlalchemy/engine/create.py", line 574, in connect
    return dialect.connect(*cargs, **cparams)
  File "/home/airflow/.local/lib/python3.8/site-packages/sqlalchemy/engine/default.py", line 598, in connect
    return self.dbapi.connect(*cargs, **cparams)
  File "/home/airflow/.local/lib/python3.8/site-packages/psycopg2/__init__.py", line 122, in connect
    conn = _connect(dsn, connection_factory=connection_factory, **kwasync)
sqlalchemy.exc.OperationalError: (psycopg2.OperationalError) could not translate host name "database" to address: Name or service not known

(Background on this error at: https://sqlalche.me/e/14/e3q8)
[2023-11-21T04:18:22.743+0000] {taskinstance.py:1400} INFO - Marking task as FAILED. dag_id=outcomes_dag, task_id=load_outcome_types_dim, execution_date=20231118T000000, start_date=20231121T041756, end_date=20231121T041822
[2023-11-21T04:18:22.922+0000] {standard_task_runner.py:104} ERROR - Failed to execute job 46 for task load_outcome_types_dim ((psycopg2.OperationalError) could not translate host name "database" to address: Name or service not known

(Background on this error at: https://sqlalche.me/e/14/e3q8); 399)
[2023-11-21T04:18:23.144+0000] {local_task_job_runner.py:228} INFO - Task exited with return code 1
[2023-11-21T04:18:23.444+0000] {taskinstance.py:2778} INFO - 0 downstream tasks scheduled from follow-on schedule check
[2023-11-21T04:47:21.072+0000] {taskinstance.py:1159} INFO - Dependencies all met for dep_context=non-requeueable deps ti=<TaskInstance: outcomes_dag.load_outcome_types_dim scheduled__2023-11-18T00:00:00+00:00 [queued]>
[2023-11-21T04:47:21.106+0000] {taskinstance.py:1159} INFO - Dependencies all met for dep_context=requeueable deps ti=<TaskInstance: outcomes_dag.load_outcome_types_dim scheduled__2023-11-18T00:00:00+00:00 [queued]>
[2023-11-21T04:47:21.113+0000] {taskinstance.py:1361} INFO - Starting attempt 1 of 1
[2023-11-21T04:47:21.221+0000] {taskinstance.py:1382} INFO - Executing <Task(PythonOperator): load_outcome_types_dim> on 2023-11-18 00:00:00+00:00
[2023-11-21T04:47:21.258+0000] {standard_task_runner.py:57} INFO - Started process 341 to run task
[2023-11-21T04:47:21.282+0000] {standard_task_runner.py:84} INFO - Running: ['***', 'tasks', 'run', 'outcomes_dag', 'load_outcome_types_dim', 'scheduled__2023-11-18T00:00:00+00:00', '--job-id', '41', '--raw', '--subdir', 'DAGS_FOLDER/outcomes_dag.py', '--cfg-path', '/tmp/tmprkoujei3']
[2023-11-21T04:47:21.296+0000] {standard_task_runner.py:85} INFO - Job 41: Subtask load_outcome_types_dim
[2023-11-21T04:47:21.540+0000] {task_command.py:416} INFO - Running <TaskInstance: outcomes_dag.load_outcome_types_dim scheduled__2023-11-18T00:00:00+00:00 [running]> on host de20a855d915
[2023-11-21T04:47:28.064+0000] {taskinstance.py:1662} INFO - Exporting env vars: AIRFLOW_CTX_DAG_OWNER='***' AIRFLOW_CTX_DAG_ID='outcomes_dag' AIRFLOW_CTX_TASK_ID='load_outcome_types_dim' AIRFLOW_CTX_EXECUTION_DATE='2023-11-18T00:00:00+00:00' AIRFLOW_CTX_TRY_NUMBER='1' AIRFLOW_CTX_DAG_RUN_ID='scheduled__2023-11-18T00:00:00+00:00'
[2023-11-21T04:47:30.982+0000] {logging_mixin.py:154} INFO - dim_outcome_types loaded
[2023-11-21T04:47:30.986+0000] {python.py:194} INFO - Done. Returned value was: None
[2023-11-21T04:47:31.070+0000] {taskinstance.py:1400} INFO - Marking task as SUCCESS. dag_id=outcomes_dag, task_id=load_outcome_types_dim, execution_date=20231118T000000, start_date=20231121T044721, end_date=20231121T044731
[2023-11-21T04:47:31.265+0000] {local_task_job_runner.py:228} INFO - Task exited with return code 0
[2023-11-21T04:47:31.425+0000] {taskinstance.py:2778} INFO - 0 downstream tasks scheduled from follow-on schedule check
[2023-11-21T04:58:05.692+0000] {taskinstance.py:1159} INFO - Dependencies all met for dep_context=non-requeueable deps ti=<TaskInstance: outcomes_dag.load_outcome_types_dim scheduled__2023-11-18T00:00:00+00:00 [queued]>
[2023-11-21T04:58:05.740+0000] {taskinstance.py:1159} INFO - Dependencies all met for dep_context=requeueable deps ti=<TaskInstance: outcomes_dag.load_outcome_types_dim scheduled__2023-11-18T00:00:00+00:00 [queued]>
[2023-11-21T04:58:05.744+0000] {taskinstance.py:1361} INFO - Starting attempt 1 of 1
[2023-11-21T04:58:05.788+0000] {taskinstance.py:1382} INFO - Executing <Task(PythonOperator): load_outcome_types_dim> on 2023-11-18 00:00:00+00:00
[2023-11-21T04:58:05.833+0000] {standard_task_runner.py:57} INFO - Started process 384 to run task
[2023-11-21T04:58:05.869+0000] {standard_task_runner.py:84} INFO - Running: ['***', 'tasks', 'run', 'outcomes_dag', 'load_outcome_types_dim', 'scheduled__2023-11-18T00:00:00+00:00', '--job-id', '43', '--raw', '--subdir', 'DAGS_FOLDER/outcomes_dag.py', '--cfg-path', '/tmp/tmp77o2rahy']
[2023-11-21T04:58:05.921+0000] {standard_task_runner.py:85} INFO - Job 43: Subtask load_outcome_types_dim
[2023-11-21T04:58:06.231+0000] {task_command.py:416} INFO - Running <TaskInstance: outcomes_dag.load_outcome_types_dim scheduled__2023-11-18T00:00:00+00:00 [running]> on host 921d770aa62c
[2023-11-21T04:58:10.614+0000] {taskinstance.py:1662} INFO - Exporting env vars: AIRFLOW_CTX_DAG_OWNER='***' AIRFLOW_CTX_DAG_ID='outcomes_dag' AIRFLOW_CTX_TASK_ID='load_outcome_types_dim' AIRFLOW_CTX_EXECUTION_DATE='2023-11-18T00:00:00+00:00' AIRFLOW_CTX_TRY_NUMBER='1' AIRFLOW_CTX_DAG_RUN_ID='scheduled__2023-11-18T00:00:00+00:00'
[2023-11-21T04:58:11.867+0000] {logging_mixin.py:154} INFO - dim_outcome_types loaded
[2023-11-21T04:58:11.874+0000] {python.py:194} INFO - Done. Returned value was: None
[2023-11-21T04:58:11.929+0000] {taskinstance.py:1400} INFO - Marking task as SUCCESS. dag_id=outcomes_dag, task_id=load_outcome_types_dim, execution_date=20231118T000000, start_date=20231121T045805, end_date=20231121T045811
[2023-11-21T04:58:12.040+0000] {local_task_job_runner.py:228} INFO - Task exited with return code 0
[2023-11-21T04:58:12.183+0000] {taskinstance.py:2778} INFO - 0 downstream tasks scheduled from follow-on schedule check
