[2023-11-21T01:00:37.483+0000] {taskinstance.py:1159} INFO - Dependencies all met for dep_context=non-requeueable deps ti=<TaskInstance: outcomes_dag.load_outcome_types_dim scheduled__2023-11-13T00:00:00+00:00 [queued]>
[2023-11-21T01:00:37.568+0000] {taskinstance.py:1159} INFO - Dependencies all met for dep_context=requeueable deps ti=<TaskInstance: outcomes_dag.load_outcome_types_dim scheduled__2023-11-13T00:00:00+00:00 [queued]>
[2023-11-21T01:00:37.570+0000] {taskinstance.py:1361} INFO - Starting attempt 1 of 1
[2023-11-21T01:00:37.712+0000] {taskinstance.py:1382} INFO - Executing <Task(PythonOperator): load_outcome_types_dim> on 2023-11-13 00:00:00+00:00
[2023-11-21T01:00:37.741+0000] {standard_task_runner.py:57} INFO - Started process 270 to run task
[2023-11-21T01:00:37.782+0000] {standard_task_runner.py:84} INFO - Running: ['***', 'tasks', 'run', 'outcomes_dag', 'load_outcome_types_dim', 'scheduled__2023-11-13T00:00:00+00:00', '--job-id', '44', '--raw', '--subdir', 'DAGS_FOLDER/outcomes_dag.py', '--cfg-path', '/tmp/tmp_6m7ya_j']
[2023-11-21T01:00:37.800+0000] {standard_task_runner.py:85} INFO - Job 44: Subtask load_outcome_types_dim
[2023-11-21T01:00:38.954+0000] {task_command.py:416} INFO - Running <TaskInstance: outcomes_dag.load_outcome_types_dim scheduled__2023-11-13T00:00:00+00:00 [running]> on host bf1573643830
[2023-11-21T01:00:50.015+0000] {taskinstance.py:1662} INFO - Exporting env vars: AIRFLOW_CTX_DAG_OWNER='***' AIRFLOW_CTX_DAG_ID='outcomes_dag' AIRFLOW_CTX_TASK_ID='load_outcome_types_dim' AIRFLOW_CTX_EXECUTION_DATE='2023-11-13T00:00:00+00:00' AIRFLOW_CTX_TRY_NUMBER='1' AIRFLOW_CTX_DAG_RUN_ID='scheduled__2023-11-13T00:00:00+00:00'
[2023-11-21T01:00:50.181+0000] {taskinstance.py:1937} ERROR - Task failed with exception
Traceback (most recent call last):
  File "/home/airflow/.local/lib/python3.8/site-packages/sqlalchemy/engine/base.py", line 1890, in _execute_context
    self.dialect.do_executemany(
  File "/home/airflow/.local/lib/python3.8/site-packages/sqlalchemy/dialects/postgresql/psycopg2.py", line 982, in do_executemany
    context._psycopg2_fetched_rows = xtras.execute_values(
  File "/home/airflow/.local/lib/python3.8/site-packages/psycopg2/extras.py", line 1299, in execute_values
    cur.execute(b''.join(parts))
psycopg2.errors.UniqueViolation: duplicate key value violates unique constraint "dim_outcome_types_pkey"
DETAIL:  Key (outcome_type_id)=(1) already exists.


The above exception was the direct cause of the following exception:

Traceback (most recent call last):
  File "/home/airflow/.local/lib/python3.8/site-packages/airflow/operators/python.py", line 192, in execute
    return_value = self.execute_callable()
  File "/home/airflow/.local/lib/python3.8/site-packages/airflow/operators/python.py", line 209, in execute_callable
    return self.python_callable(*self.op_args, **self.op_kwargs)
  File "/opt/airflow/dags/etl_scripts/load.py", line 20, in load_data
    pd.read_parquet(table_file).to_sql(table_name, conn, if_exists="append", index=False)
  File "/home/airflow/.local/lib/python3.8/site-packages/pandas/core/generic.py", line 2878, in to_sql
    return sql.to_sql(
  File "/home/airflow/.local/lib/python3.8/site-packages/pandas/io/sql.py", line 769, in to_sql
    return pandas_sql.to_sql(
  File "/home/airflow/.local/lib/python3.8/site-packages/pandas/io/sql.py", line 1920, in to_sql
    total_inserted = sql_engine.insert_records(
  File "/home/airflow/.local/lib/python3.8/site-packages/pandas/io/sql.py", line 1470, in insert_records
    raise err
  File "/home/airflow/.local/lib/python3.8/site-packages/pandas/io/sql.py", line 1461, in insert_records
    return table.insert(chunksize=chunksize, method=method)
  File "/home/airflow/.local/lib/python3.8/site-packages/pandas/io/sql.py", line 1023, in insert
    num_inserted = exec_insert(conn, keys, chunk_iter)
  File "/home/airflow/.local/lib/python3.8/site-packages/pandas/io/sql.py", line 929, in _execute_insert
    result = conn.execute(self.table.insert(), data)
  File "/home/airflow/.local/lib/python3.8/site-packages/sqlalchemy/engine/base.py", line 1385, in execute
    return meth(self, multiparams, params, _EMPTY_EXECUTION_OPTS)
  File "/home/airflow/.local/lib/python3.8/site-packages/sqlalchemy/sql/elements.py", line 334, in _execute_on_connection
    return connection._execute_clauseelement(
  File "/home/airflow/.local/lib/python3.8/site-packages/sqlalchemy/engine/base.py", line 1577, in _execute_clauseelement
    ret = self._execute_context(
  File "/home/airflow/.local/lib/python3.8/site-packages/sqlalchemy/engine/base.py", line 1953, in _execute_context
    self._handle_dbapi_exception(
  File "/home/airflow/.local/lib/python3.8/site-packages/sqlalchemy/engine/base.py", line 2134, in _handle_dbapi_exception
    util.raise_(
  File "/home/airflow/.local/lib/python3.8/site-packages/sqlalchemy/util/compat.py", line 211, in raise_
    raise exception
  File "/home/airflow/.local/lib/python3.8/site-packages/sqlalchemy/engine/base.py", line 1890, in _execute_context
    self.dialect.do_executemany(
  File "/home/airflow/.local/lib/python3.8/site-packages/sqlalchemy/dialects/postgresql/psycopg2.py", line 982, in do_executemany
    context._psycopg2_fetched_rows = xtras.execute_values(
  File "/home/airflow/.local/lib/python3.8/site-packages/psycopg2/extras.py", line 1299, in execute_values
    cur.execute(b''.join(parts))
sqlalchemy.exc.IntegrityError: (psycopg2.errors.UniqueViolation) duplicate key value violates unique constraint "dim_outcome_types_pkey"
DETAIL:  Key (outcome_type_id)=(1) already exists.

[SQL: INSERT INTO dim_outcome_types (outcome_type, outcome_type_id) VALUES (%(outcome_type)s, %(outcome_type_id)s)]
[parameters: ({'outcome_type': 'Rto-Adopt', 'outcome_type_id': 1}, {'outcome_type': 'Adoption', 'outcome_type_id': 2}, {'outcome_type': 'Euthanasia', 'outcome_type_id': 3}, {'outcome_type': 'Transfer', 'outcome_type_id': 4}, {'outcome_type': 'Return to Owner', 'outcome_type_id': 5}, {'outcome_type': 'Died', 'outcome_type_id': 6}, {'outcome_type': 'Disposal', 'outcome_type_id': 7}, {'outcome_type': 'Missing', 'outcome_type_id': 8}  ... displaying 10 of 11 total bound parameter sets ...  {'outcome_type': 'N/A', 'outcome_type_id': 10}, {'outcome_type': 'Stolen', 'outcome_type_id': 11})]
(Background on this error at: https://sqlalche.me/e/14/gkpj)
[2023-11-21T01:00:50.219+0000] {taskinstance.py:1400} INFO - Marking task as FAILED. dag_id=outcomes_dag, task_id=load_outcome_types_dim, execution_date=20231113T000000, start_date=20231121T010037, end_date=20231121T010050
[2023-11-21T01:00:50.260+0000] {standard_task_runner.py:104} ERROR - Failed to execute job 44 for task load_outcome_types_dim ((psycopg2.errors.UniqueViolation) duplicate key value violates unique constraint "dim_outcome_types_pkey"
DETAIL:  Key (outcome_type_id)=(1) already exists.

[SQL: INSERT INTO dim_outcome_types (outcome_type, outcome_type_id) VALUES (%(outcome_type)s, %(outcome_type_id)s)]
[parameters: ({'outcome_type': 'Rto-Adopt', 'outcome_type_id': 1}, {'outcome_type': 'Adoption', 'outcome_type_id': 2}, {'outcome_type': 'Euthanasia', 'outcome_type_id': 3}, {'outcome_type': 'Transfer', 'outcome_type_id': 4}, {'outcome_type': 'Return to Owner', 'outcome_type_id': 5}, {'outcome_type': 'Died', 'outcome_type_id': 6}, {'outcome_type': 'Disposal', 'outcome_type_id': 7}, {'outcome_type': 'Missing', 'outcome_type_id': 8}  ... displaying 10 of 11 total bound parameter sets ...  {'outcome_type': 'N/A', 'outcome_type_id': 10}, {'outcome_type': 'Stolen', 'outcome_type_id': 11})]
(Background on this error at: https://sqlalche.me/e/14/gkpj); 270)
[2023-11-21T01:00:50.336+0000] {local_task_job_runner.py:228} INFO - Task exited with return code 1
[2023-11-21T01:00:50.386+0000] {taskinstance.py:2778} INFO - 0 downstream tasks scheduled from follow-on schedule check
[2023-11-21T01:14:52.667+0000] {taskinstance.py:1159} INFO - Dependencies all met for dep_context=non-requeueable deps ti=<TaskInstance: outcomes_dag.load_outcome_types_dim scheduled__2023-11-13T00:00:00+00:00 [queued]>
[2023-11-21T01:14:52.716+0000] {taskinstance.py:1159} INFO - Dependencies all met for dep_context=requeueable deps ti=<TaskInstance: outcomes_dag.load_outcome_types_dim scheduled__2023-11-13T00:00:00+00:00 [queued]>
[2023-11-21T01:14:52.719+0000] {taskinstance.py:1361} INFO - Starting attempt 1 of 1
[2023-11-21T01:14:52.761+0000] {taskinstance.py:1382} INFO - Executing <Task(PythonOperator): load_outcome_types_dim> on 2023-11-13 00:00:00+00:00
[2023-11-21T01:14:52.798+0000] {standard_task_runner.py:57} INFO - Started process 330 to run task
[2023-11-21T01:14:52.831+0000] {standard_task_runner.py:84} INFO - Running: ['***', 'tasks', 'run', 'outcomes_dag', 'load_outcome_types_dim', 'scheduled__2023-11-13T00:00:00+00:00', '--job-id', '42', '--raw', '--subdir', 'DAGS_FOLDER/outcomes_dag.py', '--cfg-path', '/tmp/tmp62xxeb5f']
[2023-11-21T01:14:52.846+0000] {standard_task_runner.py:85} INFO - Job 42: Subtask load_outcome_types_dim
[2023-11-21T01:14:53.125+0000] {task_command.py:416} INFO - Running <TaskInstance: outcomes_dag.load_outcome_types_dim scheduled__2023-11-13T00:00:00+00:00 [running]> on host 9a73044c5577
[2023-11-21T01:14:56.488+0000] {taskinstance.py:1662} INFO - Exporting env vars: AIRFLOW_CTX_DAG_OWNER='***' AIRFLOW_CTX_DAG_ID='outcomes_dag' AIRFLOW_CTX_TASK_ID='load_outcome_types_dim' AIRFLOW_CTX_EXECUTION_DATE='2023-11-13T00:00:00+00:00' AIRFLOW_CTX_TRY_NUMBER='1' AIRFLOW_CTX_DAG_RUN_ID='scheduled__2023-11-13T00:00:00+00:00'
[2023-11-21T01:14:58.937+0000] {taskinstance.py:1937} ERROR - Task failed with exception
Traceback (most recent call last):
  File "/home/airflow/.local/lib/python3.8/site-packages/sqlalchemy/engine/base.py", line 1890, in _execute_context
    self.dialect.do_executemany(
  File "/home/airflow/.local/lib/python3.8/site-packages/sqlalchemy/dialects/postgresql/psycopg2.py", line 982, in do_executemany
    context._psycopg2_fetched_rows = xtras.execute_values(
  File "/home/airflow/.local/lib/python3.8/site-packages/psycopg2/extras.py", line 1299, in execute_values
    cur.execute(b''.join(parts))
psycopg2.errors.UniqueViolation: duplicate key value violates unique constraint "dim_outcome_types_pkey"
DETAIL:  Key (outcome_type_id)=(1) already exists.


The above exception was the direct cause of the following exception:

Traceback (most recent call last):
  File "/home/airflow/.local/lib/python3.8/site-packages/airflow/operators/python.py", line 192, in execute
    return_value = self.execute_callable()
  File "/home/airflow/.local/lib/python3.8/site-packages/airflow/operators/python.py", line 209, in execute_callable
    return self.python_callable(*self.op_args, **self.op_kwargs)
  File "/opt/airflow/dags/etl_scripts/load.py", line 20, in load_data
    pd.read_parquet(table_file).to_sql(table_name, conn, if_exists="append", index=False)
  File "/home/airflow/.local/lib/python3.8/site-packages/pandas/core/generic.py", line 2878, in to_sql
    return sql.to_sql(
  File "/home/airflow/.local/lib/python3.8/site-packages/pandas/io/sql.py", line 769, in to_sql
    return pandas_sql.to_sql(
  File "/home/airflow/.local/lib/python3.8/site-packages/pandas/io/sql.py", line 1920, in to_sql
    total_inserted = sql_engine.insert_records(
  File "/home/airflow/.local/lib/python3.8/site-packages/pandas/io/sql.py", line 1470, in insert_records
    raise err
  File "/home/airflow/.local/lib/python3.8/site-packages/pandas/io/sql.py", line 1461, in insert_records
    return table.insert(chunksize=chunksize, method=method)
  File "/home/airflow/.local/lib/python3.8/site-packages/pandas/io/sql.py", line 1023, in insert
    num_inserted = exec_insert(conn, keys, chunk_iter)
  File "/home/airflow/.local/lib/python3.8/site-packages/pandas/io/sql.py", line 929, in _execute_insert
    result = conn.execute(self.table.insert(), data)
  File "/home/airflow/.local/lib/python3.8/site-packages/sqlalchemy/engine/base.py", line 1385, in execute
    return meth(self, multiparams, params, _EMPTY_EXECUTION_OPTS)
  File "/home/airflow/.local/lib/python3.8/site-packages/sqlalchemy/sql/elements.py", line 334, in _execute_on_connection
    return connection._execute_clauseelement(
  File "/home/airflow/.local/lib/python3.8/site-packages/sqlalchemy/engine/base.py", line 1577, in _execute_clauseelement
    ret = self._execute_context(
  File "/home/airflow/.local/lib/python3.8/site-packages/sqlalchemy/engine/base.py", line 1953, in _execute_context
    self._handle_dbapi_exception(
  File "/home/airflow/.local/lib/python3.8/site-packages/sqlalchemy/engine/base.py", line 2134, in _handle_dbapi_exception
    util.raise_(
  File "/home/airflow/.local/lib/python3.8/site-packages/sqlalchemy/util/compat.py", line 211, in raise_
    raise exception
  File "/home/airflow/.local/lib/python3.8/site-packages/sqlalchemy/engine/base.py", line 1890, in _execute_context
    self.dialect.do_executemany(
  File "/home/airflow/.local/lib/python3.8/site-packages/sqlalchemy/dialects/postgresql/psycopg2.py", line 982, in do_executemany
    context._psycopg2_fetched_rows = xtras.execute_values(
  File "/home/airflow/.local/lib/python3.8/site-packages/psycopg2/extras.py", line 1299, in execute_values
    cur.execute(b''.join(parts))
sqlalchemy.exc.IntegrityError: (psycopg2.errors.UniqueViolation) duplicate key value violates unique constraint "dim_outcome_types_pkey"
DETAIL:  Key (outcome_type_id)=(1) already exists.

[SQL: INSERT INTO dim_outcome_types (outcome_type, outcome_type_id) VALUES (%(outcome_type)s, %(outcome_type_id)s)]
[parameters: ({'outcome_type': 'Rto-Adopt', 'outcome_type_id': 1}, {'outcome_type': 'Adoption', 'outcome_type_id': 2}, {'outcome_type': 'Euthanasia', 'outcome_type_id': 3}, {'outcome_type': 'Transfer', 'outcome_type_id': 4}, {'outcome_type': 'Return to Owner', 'outcome_type_id': 5}, {'outcome_type': 'Died', 'outcome_type_id': 6}, {'outcome_type': 'Disposal', 'outcome_type_id': 7}, {'outcome_type': 'Missing', 'outcome_type_id': 8}  ... displaying 10 of 11 total bound parameter sets ...  {'outcome_type': 'N/A', 'outcome_type_id': 10}, {'outcome_type': 'Stolen', 'outcome_type_id': 11})]
(Background on this error at: https://sqlalche.me/e/14/gkpj)
[2023-11-21T01:14:59.327+0000] {taskinstance.py:1400} INFO - Marking task as FAILED. dag_id=outcomes_dag, task_id=load_outcome_types_dim, execution_date=20231113T000000, start_date=20231121T011452, end_date=20231121T011459
[2023-11-21T01:14:59.420+0000] {standard_task_runner.py:104} ERROR - Failed to execute job 42 for task load_outcome_types_dim ((psycopg2.errors.UniqueViolation) duplicate key value violates unique constraint "dim_outcome_types_pkey"
DETAIL:  Key (outcome_type_id)=(1) already exists.

[SQL: INSERT INTO dim_outcome_types (outcome_type, outcome_type_id) VALUES (%(outcome_type)s, %(outcome_type_id)s)]
[parameters: ({'outcome_type': 'Rto-Adopt', 'outcome_type_id': 1}, {'outcome_type': 'Adoption', 'outcome_type_id': 2}, {'outcome_type': 'Euthanasia', 'outcome_type_id': 3}, {'outcome_type': 'Transfer', 'outcome_type_id': 4}, {'outcome_type': 'Return to Owner', 'outcome_type_id': 5}, {'outcome_type': 'Died', 'outcome_type_id': 6}, {'outcome_type': 'Disposal', 'outcome_type_id': 7}, {'outcome_type': 'Missing', 'outcome_type_id': 8}  ... displaying 10 of 11 total bound parameter sets ...  {'outcome_type': 'N/A', 'outcome_type_id': 10}, {'outcome_type': 'Stolen', 'outcome_type_id': 11})]
(Background on this error at: https://sqlalche.me/e/14/gkpj); 330)
[2023-11-21T01:14:59.521+0000] {local_task_job_runner.py:228} INFO - Task exited with return code 1
[2023-11-21T01:14:59.728+0000] {taskinstance.py:2778} INFO - 0 downstream tasks scheduled from follow-on schedule check
