[2023-11-21T00:00:20.703+0000] {taskinstance.py:1159} INFO - Dependencies all met for dep_context=non-requeueable deps ti=<TaskInstance: outcomes_dag.load_outcome_types_dim scheduled__2023-11-20T00:00:00+00:00 [queued]>
[2023-11-21T00:00:20.710+0000] {taskinstance.py:1159} INFO - Dependencies all met for dep_context=requeueable deps ti=<TaskInstance: outcomes_dag.load_outcome_types_dim scheduled__2023-11-20T00:00:00+00:00 [queued]>
[2023-11-21T00:00:20.711+0000] {taskinstance.py:1361} INFO - Starting attempt 1 of 1
[2023-11-21T00:00:20.719+0000] {taskinstance.py:1382} INFO - Executing <Task(PythonOperator): load_outcome_types_dim> on 2023-11-20 00:00:00+00:00
[2023-11-21T00:00:20.724+0000] {standard_task_runner.py:57} INFO - Started process 448 to run task
[2023-11-21T00:00:20.728+0000] {standard_task_runner.py:84} INFO - Running: ['***', 'tasks', 'run', 'outcomes_dag', 'load_outcome_types_dim', 'scheduled__2023-11-20T00:00:00+00:00', '--job-id', '50', '--raw', '--subdir', 'DAGS_FOLDER/outcomes_dag.py', '--cfg-path', '/tmp/tmpel6z9a9v']
[2023-11-21T00:00:20.732+0000] {standard_task_runner.py:85} INFO - Job 50: Subtask load_outcome_types_dim
[2023-11-21T00:00:20.786+0000] {task_command.py:416} INFO - Running <TaskInstance: outcomes_dag.load_outcome_types_dim scheduled__2023-11-20T00:00:00+00:00 [running]> on host 3aa39f73e581
[2023-11-21T00:00:22.029+0000] {taskinstance.py:1662} INFO - Exporting env vars: AIRFLOW_CTX_DAG_OWNER='***' AIRFLOW_CTX_DAG_ID='outcomes_dag' AIRFLOW_CTX_TASK_ID='load_outcome_types_dim' AIRFLOW_CTX_EXECUTION_DATE='2023-11-20T00:00:00+00:00' AIRFLOW_CTX_TRY_NUMBER='1' AIRFLOW_CTX_DAG_RUN_ID='scheduled__2023-11-20T00:00:00+00:00'
[2023-11-21T00:00:22.091+0000] {taskinstance.py:1937} ERROR - Task failed with exception
Traceback (most recent call last):
  File "/home/airflow/.local/lib/python3.8/site-packages/sqlalchemy/engine/base.py", line 1890, in _execute_context
    self.dialect.do_executemany(
  File "/home/airflow/.local/lib/python3.8/site-packages/sqlalchemy/dialects/postgresql/psycopg2.py", line 982, in do_executemany
    context._psycopg2_fetched_rows = xtras.execute_values(
  File "/home/airflow/.local/lib/python3.8/site-packages/psycopg2/extras.py", line 1299, in execute_values
    cur.execute(b''.join(parts))
psycopg2.errors.UniqueViolation: duplicate key value violates unique constraint "dim_outcome_types_pkey"
DETAIL:  Key (outcome_type_id)=(1) already exists.


The above exception was the direct cause of the following exception:

Traceback (most recent call last):
  File "/home/airflow/.local/lib/python3.8/site-packages/airflow/operators/python.py", line 192, in execute
    return_value = self.execute_callable()
  File "/home/airflow/.local/lib/python3.8/site-packages/airflow/operators/python.py", line 209, in execute_callable
    return self.python_callable(*self.op_args, **self.op_kwargs)
  File "/opt/airflow/dags/etl_scripts/load.py", line 20, in load_data
    pd.read_parquet(table_file).to_sql(table_name, conn, if_exists="append", index=False)
  File "/home/airflow/.local/lib/python3.8/site-packages/pandas/core/generic.py", line 2878, in to_sql
    return sql.to_sql(
  File "/home/airflow/.local/lib/python3.8/site-packages/pandas/io/sql.py", line 769, in to_sql
    return pandas_sql.to_sql(
  File "/home/airflow/.local/lib/python3.8/site-packages/pandas/io/sql.py", line 1920, in to_sql
    total_inserted = sql_engine.insert_records(
  File "/home/airflow/.local/lib/python3.8/site-packages/pandas/io/sql.py", line 1470, in insert_records
    raise err
  File "/home/airflow/.local/lib/python3.8/site-packages/pandas/io/sql.py", line 1461, in insert_records
    return table.insert(chunksize=chunksize, method=method)
  File "/home/airflow/.local/lib/python3.8/site-packages/pandas/io/sql.py", line 1023, in insert
    num_inserted = exec_insert(conn, keys, chunk_iter)
  File "/home/airflow/.local/lib/python3.8/site-packages/pandas/io/sql.py", line 929, in _execute_insert
    result = conn.execute(self.table.insert(), data)
  File "/home/airflow/.local/lib/python3.8/site-packages/sqlalchemy/engine/base.py", line 1385, in execute
    return meth(self, multiparams, params, _EMPTY_EXECUTION_OPTS)
  File "/home/airflow/.local/lib/python3.8/site-packages/sqlalchemy/sql/elements.py", line 334, in _execute_on_connection
    return connection._execute_clauseelement(
  File "/home/airflow/.local/lib/python3.8/site-packages/sqlalchemy/engine/base.py", line 1577, in _execute_clauseelement
    ret = self._execute_context(
  File "/home/airflow/.local/lib/python3.8/site-packages/sqlalchemy/engine/base.py", line 1953, in _execute_context
    self._handle_dbapi_exception(
  File "/home/airflow/.local/lib/python3.8/site-packages/sqlalchemy/engine/base.py", line 2134, in _handle_dbapi_exception
    util.raise_(
  File "/home/airflow/.local/lib/python3.8/site-packages/sqlalchemy/util/compat.py", line 211, in raise_
    raise exception
  File "/home/airflow/.local/lib/python3.8/site-packages/sqlalchemy/engine/base.py", line 1890, in _execute_context
    self.dialect.do_executemany(
  File "/home/airflow/.local/lib/python3.8/site-packages/sqlalchemy/dialects/postgresql/psycopg2.py", line 982, in do_executemany
    context._psycopg2_fetched_rows = xtras.execute_values(
  File "/home/airflow/.local/lib/python3.8/site-packages/psycopg2/extras.py", line 1299, in execute_values
    cur.execute(b''.join(parts))
sqlalchemy.exc.IntegrityError: (psycopg2.errors.UniqueViolation) duplicate key value violates unique constraint "dim_outcome_types_pkey"
DETAIL:  Key (outcome_type_id)=(1) already exists.

[SQL: INSERT INTO dim_outcome_types (outcome_type, outcome_type_id) VALUES (%(outcome_type)s, %(outcome_type_id)s)]
[parameters: ({'outcome_type': 'Rto-Adopt', 'outcome_type_id': 1}, {'outcome_type': 'Adoption', 'outcome_type_id': 2}, {'outcome_type': 'Euthanasia', 'outcome_type_id': 3}, {'outcome_type': 'Transfer', 'outcome_type_id': 4}, {'outcome_type': 'Return to Owner', 'outcome_type_id': 5}, {'outcome_type': 'Died', 'outcome_type_id': 6}, {'outcome_type': 'Disposal', 'outcome_type_id': 7}, {'outcome_type': 'Missing', 'outcome_type_id': 8}  ... displaying 10 of 11 total bound parameter sets ...  {'outcome_type': 'N/A', 'outcome_type_id': 10}, {'outcome_type': 'Stolen', 'outcome_type_id': 11})]
(Background on this error at: https://sqlalche.me/e/14/gkpj)
[2023-11-21T00:00:22.101+0000] {taskinstance.py:1400} INFO - Marking task as FAILED. dag_id=outcomes_dag, task_id=load_outcome_types_dim, execution_date=20231120T000000, start_date=20231121T000020, end_date=20231121T000022
[2023-11-21T00:00:22.108+0000] {standard_task_runner.py:104} ERROR - Failed to execute job 50 for task load_outcome_types_dim ((psycopg2.errors.UniqueViolation) duplicate key value violates unique constraint "dim_outcome_types_pkey"
DETAIL:  Key (outcome_type_id)=(1) already exists.

[SQL: INSERT INTO dim_outcome_types (outcome_type, outcome_type_id) VALUES (%(outcome_type)s, %(outcome_type_id)s)]
[parameters: ({'outcome_type': 'Rto-Adopt', 'outcome_type_id': 1}, {'outcome_type': 'Adoption', 'outcome_type_id': 2}, {'outcome_type': 'Euthanasia', 'outcome_type_id': 3}, {'outcome_type': 'Transfer', 'outcome_type_id': 4}, {'outcome_type': 'Return to Owner', 'outcome_type_id': 5}, {'outcome_type': 'Died', 'outcome_type_id': 6}, {'outcome_type': 'Disposal', 'outcome_type_id': 7}, {'outcome_type': 'Missing', 'outcome_type_id': 8}  ... displaying 10 of 11 total bound parameter sets ...  {'outcome_type': 'N/A', 'outcome_type_id': 10}, {'outcome_type': 'Stolen', 'outcome_type_id': 11})]
(Background on this error at: https://sqlalche.me/e/14/gkpj); 448)
[2023-11-21T00:00:22.134+0000] {local_task_job_runner.py:228} INFO - Task exited with return code 1
[2023-11-21T00:00:22.178+0000] {taskinstance.py:2778} INFO - 0 downstream tasks scheduled from follow-on schedule check
[2023-11-21T01:15:12.819+0000] {taskinstance.py:1159} INFO - Dependencies all met for dep_context=non-requeueable deps ti=<TaskInstance: outcomes_dag.load_outcome_types_dim scheduled__2023-11-20T00:00:00+00:00 [queued]>
[2023-11-21T01:15:12.824+0000] {taskinstance.py:1159} INFO - Dependencies all met for dep_context=requeueable deps ti=<TaskInstance: outcomes_dag.load_outcome_types_dim scheduled__2023-11-20T00:00:00+00:00 [queued]>
[2023-11-21T01:15:12.825+0000] {taskinstance.py:1361} INFO - Starting attempt 1 of 1
[2023-11-21T01:15:12.832+0000] {taskinstance.py:1382} INFO - Executing <Task(PythonOperator): load_outcome_types_dim> on 2023-11-20 00:00:00+00:00
[2023-11-21T01:15:12.838+0000] {standard_task_runner.py:57} INFO - Started process 396 to run task
[2023-11-21T01:15:12.843+0000] {standard_task_runner.py:84} INFO - Running: ['***', 'tasks', 'run', 'outcomes_dag', 'load_outcome_types_dim', 'scheduled__2023-11-20T00:00:00+00:00', '--job-id', '47', '--raw', '--subdir', 'DAGS_FOLDER/outcomes_dag.py', '--cfg-path', '/tmp/tmpxtkth4g3']
[2023-11-21T01:15:12.847+0000] {standard_task_runner.py:85} INFO - Job 47: Subtask load_outcome_types_dim
[2023-11-21T01:15:12.882+0000] {task_command.py:416} INFO - Running <TaskInstance: outcomes_dag.load_outcome_types_dim scheduled__2023-11-20T00:00:00+00:00 [running]> on host 9a73044c5577
[2023-11-21T01:15:13.836+0000] {taskinstance.py:1662} INFO - Exporting env vars: AIRFLOW_CTX_DAG_OWNER='***' AIRFLOW_CTX_DAG_ID='outcomes_dag' AIRFLOW_CTX_TASK_ID='load_outcome_types_dim' AIRFLOW_CTX_EXECUTION_DATE='2023-11-20T00:00:00+00:00' AIRFLOW_CTX_TRY_NUMBER='1' AIRFLOW_CTX_DAG_RUN_ID='scheduled__2023-11-20T00:00:00+00:00'
[2023-11-21T01:15:13.935+0000] {taskinstance.py:1937} ERROR - Task failed with exception
Traceback (most recent call last):
  File "/home/airflow/.local/lib/python3.8/site-packages/sqlalchemy/engine/base.py", line 1890, in _execute_context
    self.dialect.do_executemany(
  File "/home/airflow/.local/lib/python3.8/site-packages/sqlalchemy/dialects/postgresql/psycopg2.py", line 982, in do_executemany
    context._psycopg2_fetched_rows = xtras.execute_values(
  File "/home/airflow/.local/lib/python3.8/site-packages/psycopg2/extras.py", line 1299, in execute_values
    cur.execute(b''.join(parts))
psycopg2.errors.UniqueViolation: duplicate key value violates unique constraint "dim_outcome_types_pkey"
DETAIL:  Key (outcome_type_id)=(1) already exists.


The above exception was the direct cause of the following exception:

Traceback (most recent call last):
  File "/home/airflow/.local/lib/python3.8/site-packages/airflow/operators/python.py", line 192, in execute
    return_value = self.execute_callable()
  File "/home/airflow/.local/lib/python3.8/site-packages/airflow/operators/python.py", line 209, in execute_callable
    return self.python_callable(*self.op_args, **self.op_kwargs)
  File "/opt/airflow/dags/etl_scripts/load.py", line 20, in load_data
    pd.read_parquet(table_file).to_sql(table_name, conn, if_exists="append", index=False)
  File "/home/airflow/.local/lib/python3.8/site-packages/pandas/core/generic.py", line 2878, in to_sql
    return sql.to_sql(
  File "/home/airflow/.local/lib/python3.8/site-packages/pandas/io/sql.py", line 769, in to_sql
    return pandas_sql.to_sql(
  File "/home/airflow/.local/lib/python3.8/site-packages/pandas/io/sql.py", line 1920, in to_sql
    total_inserted = sql_engine.insert_records(
  File "/home/airflow/.local/lib/python3.8/site-packages/pandas/io/sql.py", line 1470, in insert_records
    raise err
  File "/home/airflow/.local/lib/python3.8/site-packages/pandas/io/sql.py", line 1461, in insert_records
    return table.insert(chunksize=chunksize, method=method)
  File "/home/airflow/.local/lib/python3.8/site-packages/pandas/io/sql.py", line 1023, in insert
    num_inserted = exec_insert(conn, keys, chunk_iter)
  File "/home/airflow/.local/lib/python3.8/site-packages/pandas/io/sql.py", line 929, in _execute_insert
    result = conn.execute(self.table.insert(), data)
  File "/home/airflow/.local/lib/python3.8/site-packages/sqlalchemy/engine/base.py", line 1385, in execute
    return meth(self, multiparams, params, _EMPTY_EXECUTION_OPTS)
  File "/home/airflow/.local/lib/python3.8/site-packages/sqlalchemy/sql/elements.py", line 334, in _execute_on_connection
    return connection._execute_clauseelement(
  File "/home/airflow/.local/lib/python3.8/site-packages/sqlalchemy/engine/base.py", line 1577, in _execute_clauseelement
    ret = self._execute_context(
  File "/home/airflow/.local/lib/python3.8/site-packages/sqlalchemy/engine/base.py", line 1953, in _execute_context
    self._handle_dbapi_exception(
  File "/home/airflow/.local/lib/python3.8/site-packages/sqlalchemy/engine/base.py", line 2134, in _handle_dbapi_exception
    util.raise_(
  File "/home/airflow/.local/lib/python3.8/site-packages/sqlalchemy/util/compat.py", line 211, in raise_
    raise exception
  File "/home/airflow/.local/lib/python3.8/site-packages/sqlalchemy/engine/base.py", line 1890, in _execute_context
    self.dialect.do_executemany(
  File "/home/airflow/.local/lib/python3.8/site-packages/sqlalchemy/dialects/postgresql/psycopg2.py", line 982, in do_executemany
    context._psycopg2_fetched_rows = xtras.execute_values(
  File "/home/airflow/.local/lib/python3.8/site-packages/psycopg2/extras.py", line 1299, in execute_values
    cur.execute(b''.join(parts))
sqlalchemy.exc.IntegrityError: (psycopg2.errors.UniqueViolation) duplicate key value violates unique constraint "dim_outcome_types_pkey"
DETAIL:  Key (outcome_type_id)=(1) already exists.

[SQL: INSERT INTO dim_outcome_types (outcome_type, outcome_type_id) VALUES (%(outcome_type)s, %(outcome_type_id)s)]
[parameters: ({'outcome_type': 'Rto-Adopt', 'outcome_type_id': 1}, {'outcome_type': 'Adoption', 'outcome_type_id': 2}, {'outcome_type': 'Euthanasia', 'outcome_type_id': 3}, {'outcome_type': 'Transfer', 'outcome_type_id': 4}, {'outcome_type': 'Return to Owner', 'outcome_type_id': 5}, {'outcome_type': 'Died', 'outcome_type_id': 6}, {'outcome_type': 'Disposal', 'outcome_type_id': 7}, {'outcome_type': 'Missing', 'outcome_type_id': 8}  ... displaying 10 of 11 total bound parameter sets ...  {'outcome_type': 'N/A', 'outcome_type_id': 10}, {'outcome_type': 'Stolen', 'outcome_type_id': 11})]
(Background on this error at: https://sqlalche.me/e/14/gkpj)
[2023-11-21T01:15:13.952+0000] {taskinstance.py:1400} INFO - Marking task as FAILED. dag_id=outcomes_dag, task_id=load_outcome_types_dim, execution_date=20231120T000000, start_date=20231121T011512, end_date=20231121T011513
[2023-11-21T01:15:13.964+0000] {standard_task_runner.py:104} ERROR - Failed to execute job 47 for task load_outcome_types_dim ((psycopg2.errors.UniqueViolation) duplicate key value violates unique constraint "dim_outcome_types_pkey"
DETAIL:  Key (outcome_type_id)=(1) already exists.

[SQL: INSERT INTO dim_outcome_types (outcome_type, outcome_type_id) VALUES (%(outcome_type)s, %(outcome_type_id)s)]
[parameters: ({'outcome_type': 'Rto-Adopt', 'outcome_type_id': 1}, {'outcome_type': 'Adoption', 'outcome_type_id': 2}, {'outcome_type': 'Euthanasia', 'outcome_type_id': 3}, {'outcome_type': 'Transfer', 'outcome_type_id': 4}, {'outcome_type': 'Return to Owner', 'outcome_type_id': 5}, {'outcome_type': 'Died', 'outcome_type_id': 6}, {'outcome_type': 'Disposal', 'outcome_type_id': 7}, {'outcome_type': 'Missing', 'outcome_type_id': 8}  ... displaying 10 of 11 total bound parameter sets ...  {'outcome_type': 'N/A', 'outcome_type_id': 10}, {'outcome_type': 'Stolen', 'outcome_type_id': 11})]
(Background on this error at: https://sqlalche.me/e/14/gkpj); 396)
[2023-11-21T01:15:14.016+0000] {local_task_job_runner.py:228} INFO - Task exited with return code 1
[2023-11-21T01:15:14.066+0000] {taskinstance.py:2778} INFO - 0 downstream tasks scheduled from follow-on schedule check
[2023-11-21T03:57:26.428+0000] {taskinstance.py:1159} INFO - Dependencies all met for dep_context=non-requeueable deps ti=<TaskInstance: outcomes_dag.load_outcome_types_dim scheduled__2023-11-20T00:00:00+00:00 [queued]>
[2023-11-21T03:57:26.522+0000] {taskinstance.py:1159} INFO - Dependencies all met for dep_context=requeueable deps ti=<TaskInstance: outcomes_dag.load_outcome_types_dim scheduled__2023-11-20T00:00:00+00:00 [queued]>
[2023-11-21T03:57:26.524+0000] {taskinstance.py:1361} INFO - Starting attempt 1 of 1
[2023-11-21T03:57:26.579+0000] {taskinstance.py:1382} INFO - Executing <Task(PythonOperator): load_outcome_types_dim> on 2023-11-20 00:00:00+00:00
[2023-11-21T03:57:26.622+0000] {standard_task_runner.py:57} INFO - Started process 802 to run task
[2023-11-21T03:57:26.642+0000] {standard_task_runner.py:84} INFO - Running: ['***', 'tasks', 'run', 'outcomes_dag', 'load_outcome_types_dim', 'scheduled__2023-11-20T00:00:00+00:00', '--job-id', '59', '--raw', '--subdir', 'DAGS_FOLDER/outcomes_dag.py', '--cfg-path', '/tmp/tmphfdow1wt']
[2023-11-21T03:57:26.667+0000] {standard_task_runner.py:85} INFO - Job 59: Subtask load_outcome_types_dim
[2023-11-21T03:57:27.077+0000] {task_command.py:416} INFO - Running <TaskInstance: outcomes_dag.load_outcome_types_dim scheduled__2023-11-20T00:00:00+00:00 [running]> on host a0f615083db8
[2023-11-21T03:57:30.947+0000] {taskinstance.py:1662} INFO - Exporting env vars: AIRFLOW_CTX_DAG_OWNER='***' AIRFLOW_CTX_DAG_ID='outcomes_dag' AIRFLOW_CTX_TASK_ID='load_outcome_types_dim' AIRFLOW_CTX_EXECUTION_DATE='2023-11-20T00:00:00+00:00' AIRFLOW_CTX_TRY_NUMBER='1' AIRFLOW_CTX_DAG_RUN_ID='scheduled__2023-11-20T00:00:00+00:00'
[2023-11-21T03:57:32.864+0000] {taskinstance.py:1937} ERROR - Task failed with exception
Traceback (most recent call last):
  File "/home/airflow/.local/lib/python3.8/site-packages/sqlalchemy/engine/base.py", line 1890, in _execute_context
    self.dialect.do_executemany(
  File "/home/airflow/.local/lib/python3.8/site-packages/sqlalchemy/dialects/postgresql/psycopg2.py", line 982, in do_executemany
    context._psycopg2_fetched_rows = xtras.execute_values(
  File "/home/airflow/.local/lib/python3.8/site-packages/psycopg2/extras.py", line 1299, in execute_values
    cur.execute(b''.join(parts))
psycopg2.errors.UniqueViolation: duplicate key value violates unique constraint "dim_outcome_types_pkey"
DETAIL:  Key (outcome_type_id)=(1) already exists.


The above exception was the direct cause of the following exception:

Traceback (most recent call last):
  File "/home/airflow/.local/lib/python3.8/site-packages/airflow/operators/python.py", line 192, in execute
    return_value = self.execute_callable()
  File "/home/airflow/.local/lib/python3.8/site-packages/airflow/operators/python.py", line 209, in execute_callable
    return self.python_callable(*self.op_args, **self.op_kwargs)
  File "/opt/airflow/dags/etl_scripts/load.py", line 20, in load_data
    pd.read_parquet(table_file).to_sql(table_name, conn, if_exists="append", index=False)
  File "/home/airflow/.local/lib/python3.8/site-packages/pandas/core/generic.py", line 2878, in to_sql
    return sql.to_sql(
  File "/home/airflow/.local/lib/python3.8/site-packages/pandas/io/sql.py", line 769, in to_sql
    return pandas_sql.to_sql(
  File "/home/airflow/.local/lib/python3.8/site-packages/pandas/io/sql.py", line 1920, in to_sql
    total_inserted = sql_engine.insert_records(
  File "/home/airflow/.local/lib/python3.8/site-packages/pandas/io/sql.py", line 1470, in insert_records
    raise err
  File "/home/airflow/.local/lib/python3.8/site-packages/pandas/io/sql.py", line 1461, in insert_records
    return table.insert(chunksize=chunksize, method=method)
  File "/home/airflow/.local/lib/python3.8/site-packages/pandas/io/sql.py", line 1023, in insert
    num_inserted = exec_insert(conn, keys, chunk_iter)
  File "/home/airflow/.local/lib/python3.8/site-packages/pandas/io/sql.py", line 929, in _execute_insert
    result = conn.execute(self.table.insert(), data)
  File "/home/airflow/.local/lib/python3.8/site-packages/sqlalchemy/engine/base.py", line 1385, in execute
    return meth(self, multiparams, params, _EMPTY_EXECUTION_OPTS)
  File "/home/airflow/.local/lib/python3.8/site-packages/sqlalchemy/sql/elements.py", line 334, in _execute_on_connection
    return connection._execute_clauseelement(
  File "/home/airflow/.local/lib/python3.8/site-packages/sqlalchemy/engine/base.py", line 1577, in _execute_clauseelement
    ret = self._execute_context(
  File "/home/airflow/.local/lib/python3.8/site-packages/sqlalchemy/engine/base.py", line 1953, in _execute_context
    self._handle_dbapi_exception(
  File "/home/airflow/.local/lib/python3.8/site-packages/sqlalchemy/engine/base.py", line 2134, in _handle_dbapi_exception
    util.raise_(
  File "/home/airflow/.local/lib/python3.8/site-packages/sqlalchemy/util/compat.py", line 211, in raise_
    raise exception
  File "/home/airflow/.local/lib/python3.8/site-packages/sqlalchemy/engine/base.py", line 1890, in _execute_context
    self.dialect.do_executemany(
  File "/home/airflow/.local/lib/python3.8/site-packages/sqlalchemy/dialects/postgresql/psycopg2.py", line 982, in do_executemany
    context._psycopg2_fetched_rows = xtras.execute_values(
  File "/home/airflow/.local/lib/python3.8/site-packages/psycopg2/extras.py", line 1299, in execute_values
    cur.execute(b''.join(parts))
sqlalchemy.exc.IntegrityError: (psycopg2.errors.UniqueViolation) duplicate key value violates unique constraint "dim_outcome_types_pkey"
DETAIL:  Key (outcome_type_id)=(1) already exists.

[SQL: INSERT INTO dim_outcome_types (outcome_type, outcome_type_id) VALUES (%(outcome_type)s, %(outcome_type_id)s)]
[parameters: ({'outcome_type': 'Rto-Adopt', 'outcome_type_id': 1}, {'outcome_type': 'Adoption', 'outcome_type_id': 2}, {'outcome_type': 'Euthanasia', 'outcome_type_id': 3}, {'outcome_type': 'Transfer', 'outcome_type_id': 4}, {'outcome_type': 'Return to Owner', 'outcome_type_id': 5}, {'outcome_type': 'Died', 'outcome_type_id': 6}, {'outcome_type': 'Disposal', 'outcome_type_id': 7}, {'outcome_type': 'Missing', 'outcome_type_id': 8}  ... displaying 10 of 11 total bound parameter sets ...  {'outcome_type': 'N/A', 'outcome_type_id': 10}, {'outcome_type': 'Stolen', 'outcome_type_id': 11})]
(Background on this error at: https://sqlalche.me/e/14/gkpj)
[2023-11-21T03:57:34.182+0000] {taskinstance.py:1400} INFO - Marking task as FAILED. dag_id=outcomes_dag, task_id=load_outcome_types_dim, execution_date=20231120T000000, start_date=20231121T035726, end_date=20231121T035734
[2023-11-21T03:57:34.347+0000] {standard_task_runner.py:104} ERROR - Failed to execute job 59 for task load_outcome_types_dim ((psycopg2.errors.UniqueViolation) duplicate key value violates unique constraint "dim_outcome_types_pkey"
DETAIL:  Key (outcome_type_id)=(1) already exists.

[SQL: INSERT INTO dim_outcome_types (outcome_type, outcome_type_id) VALUES (%(outcome_type)s, %(outcome_type_id)s)]
[parameters: ({'outcome_type': 'Rto-Adopt', 'outcome_type_id': 1}, {'outcome_type': 'Adoption', 'outcome_type_id': 2}, {'outcome_type': 'Euthanasia', 'outcome_type_id': 3}, {'outcome_type': 'Transfer', 'outcome_type_id': 4}, {'outcome_type': 'Return to Owner', 'outcome_type_id': 5}, {'outcome_type': 'Died', 'outcome_type_id': 6}, {'outcome_type': 'Disposal', 'outcome_type_id': 7}, {'outcome_type': 'Missing', 'outcome_type_id': 8}  ... displaying 10 of 11 total bound parameter sets ...  {'outcome_type': 'N/A', 'outcome_type_id': 10}, {'outcome_type': 'Stolen', 'outcome_type_id': 11})]
(Background on this error at: https://sqlalche.me/e/14/gkpj); 802)
[2023-11-21T03:57:34.406+0000] {local_task_job_runner.py:228} INFO - Task exited with return code 1
[2023-11-21T03:57:34.505+0000] {taskinstance.py:2778} INFO - 0 downstream tasks scheduled from follow-on schedule check
[2023-11-21T04:18:20.537+0000] {taskinstance.py:1159} INFO - Dependencies all met for dep_context=non-requeueable deps ti=<TaskInstance: outcomes_dag.load_outcome_types_dim scheduled__2023-11-20T00:00:00+00:00 [queued]>
[2023-11-21T04:18:20.672+0000] {taskinstance.py:1159} INFO - Dependencies all met for dep_context=requeueable deps ti=<TaskInstance: outcomes_dag.load_outcome_types_dim scheduled__2023-11-20T00:00:00+00:00 [queued]>
[2023-11-21T04:18:20.692+0000] {taskinstance.py:1361} INFO - Starting attempt 1 of 1
[2023-11-21T04:18:20.879+0000] {taskinstance.py:1382} INFO - Executing <Task(PythonOperator): load_outcome_types_dim> on 2023-11-20 00:00:00+00:00
[2023-11-21T04:18:20.938+0000] {standard_task_runner.py:57} INFO - Started process 427 to run task
[2023-11-21T04:18:21.115+0000] {standard_task_runner.py:84} INFO - Running: ['***', 'tasks', 'run', 'outcomes_dag', 'load_outcome_types_dim', 'scheduled__2023-11-20T00:00:00+00:00', '--job-id', '52', '--raw', '--subdir', 'DAGS_FOLDER/outcomes_dag.py', '--cfg-path', '/tmp/tmp15qys9b0']
[2023-11-21T04:18:21.228+0000] {standard_task_runner.py:85} INFO - Job 52: Subtask load_outcome_types_dim
[2023-11-21T04:18:22.034+0000] {task_command.py:416} INFO - Running <TaskInstance: outcomes_dag.load_outcome_types_dim scheduled__2023-11-20T00:00:00+00:00 [running]> on host dc3ce06c67c1
[2023-11-21T04:18:28.559+0000] {taskinstance.py:1662} INFO - Exporting env vars: AIRFLOW_CTX_DAG_OWNER='***' AIRFLOW_CTX_DAG_ID='outcomes_dag' AIRFLOW_CTX_TASK_ID='load_outcome_types_dim' AIRFLOW_CTX_EXECUTION_DATE='2023-11-20T00:00:00+00:00' AIRFLOW_CTX_TRY_NUMBER='1' AIRFLOW_CTX_DAG_RUN_ID='scheduled__2023-11-20T00:00:00+00:00'
[2023-11-21T04:18:28.814+0000] {taskinstance.py:1937} ERROR - Task failed with exception
Traceback (most recent call last):
  File "/home/airflow/.local/lib/python3.8/site-packages/sqlalchemy/engine/base.py", line 3371, in _wrap_pool_connect
    return fn()
  File "/home/airflow/.local/lib/python3.8/site-packages/sqlalchemy/pool/base.py", line 327, in connect
    return _ConnectionFairy._checkout(self)
  File "/home/airflow/.local/lib/python3.8/site-packages/sqlalchemy/pool/base.py", line 894, in _checkout
    fairy = _ConnectionRecord.checkout(pool)
  File "/home/airflow/.local/lib/python3.8/site-packages/sqlalchemy/pool/base.py", line 493, in checkout
    rec = pool._do_get()
  File "/home/airflow/.local/lib/python3.8/site-packages/sqlalchemy/pool/impl.py", line 146, in _do_get
    self._dec_overflow()
  File "/home/airflow/.local/lib/python3.8/site-packages/sqlalchemy/util/langhelpers.py", line 70, in __exit__
    compat.raise_(
  File "/home/airflow/.local/lib/python3.8/site-packages/sqlalchemy/util/compat.py", line 211, in raise_
    raise exception
  File "/home/airflow/.local/lib/python3.8/site-packages/sqlalchemy/pool/impl.py", line 143, in _do_get
    return self._create_connection()
  File "/home/airflow/.local/lib/python3.8/site-packages/sqlalchemy/pool/base.py", line 273, in _create_connection
    return _ConnectionRecord(self)
  File "/home/airflow/.local/lib/python3.8/site-packages/sqlalchemy/pool/base.py", line 388, in __init__
    self.__connect()
  File "/home/airflow/.local/lib/python3.8/site-packages/sqlalchemy/pool/base.py", line 691, in __connect
    pool.logger.debug("Error on connect(): %s", e)
  File "/home/airflow/.local/lib/python3.8/site-packages/sqlalchemy/util/langhelpers.py", line 70, in __exit__
    compat.raise_(
  File "/home/airflow/.local/lib/python3.8/site-packages/sqlalchemy/util/compat.py", line 211, in raise_
    raise exception
  File "/home/airflow/.local/lib/python3.8/site-packages/sqlalchemy/pool/base.py", line 686, in __connect
    self.dbapi_connection = connection = pool._invoke_creator(self)
  File "/home/airflow/.local/lib/python3.8/site-packages/sqlalchemy/engine/create.py", line 574, in connect
    return dialect.connect(*cargs, **cparams)
  File "/home/airflow/.local/lib/python3.8/site-packages/sqlalchemy/engine/default.py", line 598, in connect
    return self.dbapi.connect(*cargs, **cparams)
  File "/home/airflow/.local/lib/python3.8/site-packages/psycopg2/__init__.py", line 122, in connect
    conn = _connect(dsn, connection_factory=connection_factory, **kwasync)
psycopg2.OperationalError: could not translate host name "database" to address: Name or service not known


The above exception was the direct cause of the following exception:

Traceback (most recent call last):
  File "/home/airflow/.local/lib/python3.8/site-packages/airflow/operators/python.py", line 192, in execute
    return_value = self.execute_callable()
  File "/home/airflow/.local/lib/python3.8/site-packages/airflow/operators/python.py", line 209, in execute_callable
    return self.python_callable(*self.op_args, **self.op_kwargs)
  File "/opt/airflow/dags/etl_scripts/load.py", line 20, in load_data
    pd.read_parquet(table_file).to_sql(table_name, conn, if_exists="append", index=False, method = insert_on_conflict_nothing)
  File "/home/airflow/.local/lib/python3.8/site-packages/pandas/core/generic.py", line 2878, in to_sql
    return sql.to_sql(
  File "/home/airflow/.local/lib/python3.8/site-packages/pandas/io/sql.py", line 768, in to_sql
    with pandasSQL_builder(con, schema=schema, need_transaction=True) as pandas_sql:
  File "/home/airflow/.local/lib/python3.8/site-packages/pandas/io/sql.py", line 832, in pandasSQL_builder
    return SQLDatabase(con, schema, need_transaction)
  File "/home/airflow/.local/lib/python3.8/site-packages/pandas/io/sql.py", line 1539, in __init__
    con = self.exit_stack.enter_context(con.connect())
  File "/home/airflow/.local/lib/python3.8/site-packages/sqlalchemy/engine/base.py", line 3325, in connect
    return self._connection_cls(self, close_with_result=close_with_result)
  File "/home/airflow/.local/lib/python3.8/site-packages/sqlalchemy/engine/base.py", line 96, in __init__
    else engine.raw_connection()
  File "/home/airflow/.local/lib/python3.8/site-packages/sqlalchemy/engine/base.py", line 3404, in raw_connection
    return self._wrap_pool_connect(self.pool.connect, _connection)
  File "/home/airflow/.local/lib/python3.8/site-packages/sqlalchemy/engine/base.py", line 3374, in _wrap_pool_connect
    Connection._handle_dbapi_exception_noconnection(
  File "/home/airflow/.local/lib/python3.8/site-packages/sqlalchemy/engine/base.py", line 2208, in _handle_dbapi_exception_noconnection
    util.raise_(
  File "/home/airflow/.local/lib/python3.8/site-packages/sqlalchemy/util/compat.py", line 211, in raise_
    raise exception
  File "/home/airflow/.local/lib/python3.8/site-packages/sqlalchemy/engine/base.py", line 3371, in _wrap_pool_connect
    return fn()
  File "/home/airflow/.local/lib/python3.8/site-packages/sqlalchemy/pool/base.py", line 327, in connect
    return _ConnectionFairy._checkout(self)
  File "/home/airflow/.local/lib/python3.8/site-packages/sqlalchemy/pool/base.py", line 894, in _checkout
    fairy = _ConnectionRecord.checkout(pool)
  File "/home/airflow/.local/lib/python3.8/site-packages/sqlalchemy/pool/base.py", line 493, in checkout
    rec = pool._do_get()
  File "/home/airflow/.local/lib/python3.8/site-packages/sqlalchemy/pool/impl.py", line 146, in _do_get
    self._dec_overflow()
  File "/home/airflow/.local/lib/python3.8/site-packages/sqlalchemy/util/langhelpers.py", line 70, in __exit__
    compat.raise_(
  File "/home/airflow/.local/lib/python3.8/site-packages/sqlalchemy/util/compat.py", line 211, in raise_
    raise exception
  File "/home/airflow/.local/lib/python3.8/site-packages/sqlalchemy/pool/impl.py", line 143, in _do_get
    return self._create_connection()
  File "/home/airflow/.local/lib/python3.8/site-packages/sqlalchemy/pool/base.py", line 273, in _create_connection
    return _ConnectionRecord(self)
  File "/home/airflow/.local/lib/python3.8/site-packages/sqlalchemy/pool/base.py", line 388, in __init__
    self.__connect()
  File "/home/airflow/.local/lib/python3.8/site-packages/sqlalchemy/pool/base.py", line 691, in __connect
    pool.logger.debug("Error on connect(): %s", e)
  File "/home/airflow/.local/lib/python3.8/site-packages/sqlalchemy/util/langhelpers.py", line 70, in __exit__
    compat.raise_(
  File "/home/airflow/.local/lib/python3.8/site-packages/sqlalchemy/util/compat.py", line 211, in raise_
    raise exception
  File "/home/airflow/.local/lib/python3.8/site-packages/sqlalchemy/pool/base.py", line 686, in __connect
    self.dbapi_connection = connection = pool._invoke_creator(self)
  File "/home/airflow/.local/lib/python3.8/site-packages/sqlalchemy/engine/create.py", line 574, in connect
    return dialect.connect(*cargs, **cparams)
  File "/home/airflow/.local/lib/python3.8/site-packages/sqlalchemy/engine/default.py", line 598, in connect
    return self.dbapi.connect(*cargs, **cparams)
  File "/home/airflow/.local/lib/python3.8/site-packages/psycopg2/__init__.py", line 122, in connect
    conn = _connect(dsn, connection_factory=connection_factory, **kwasync)
sqlalchemy.exc.OperationalError: (psycopg2.OperationalError) could not translate host name "database" to address: Name or service not known

(Background on this error at: https://sqlalche.me/e/14/e3q8)
[2023-11-21T04:18:28.913+0000] {taskinstance.py:1400} INFO - Marking task as FAILED. dag_id=outcomes_dag, task_id=load_outcome_types_dim, execution_date=20231120T000000, start_date=20231121T041820, end_date=20231121T041828
[2023-11-21T04:18:28.985+0000] {standard_task_runner.py:104} ERROR - Failed to execute job 52 for task load_outcome_types_dim ((psycopg2.OperationalError) could not translate host name "database" to address: Name or service not known

(Background on this error at: https://sqlalche.me/e/14/e3q8); 427)
[2023-11-21T04:18:29.101+0000] {local_task_job_runner.py:228} INFO - Task exited with return code 1
[2023-11-21T04:18:29.232+0000] {taskinstance.py:2778} INFO - 0 downstream tasks scheduled from follow-on schedule check
[2023-11-21T04:58:15.780+0000] {taskinstance.py:1159} INFO - Dependencies all met for dep_context=non-requeueable deps ti=<TaskInstance: outcomes_dag.load_outcome_types_dim scheduled__2023-11-20T00:00:00+00:00 [queued]>
[2023-11-21T04:58:15.793+0000] {taskinstance.py:1159} INFO - Dependencies all met for dep_context=requeueable deps ti=<TaskInstance: outcomes_dag.load_outcome_types_dim scheduled__2023-11-20T00:00:00+00:00 [queued]>
[2023-11-21T04:58:15.794+0000] {taskinstance.py:1361} INFO - Starting attempt 1 of 1
[2023-11-21T04:58:15.808+0000] {taskinstance.py:1382} INFO - Executing <Task(PythonOperator): load_outcome_types_dim> on 2023-11-20 00:00:00+00:00
[2023-11-21T04:58:15.818+0000] {standard_task_runner.py:57} INFO - Started process 455 to run task
[2023-11-21T04:58:15.822+0000] {standard_task_runner.py:84} INFO - Running: ['***', 'tasks', 'run', 'outcomes_dag', 'load_outcome_types_dim', 'scheduled__2023-11-20T00:00:00+00:00', '--job-id', '48', '--raw', '--subdir', 'DAGS_FOLDER/outcomes_dag.py', '--cfg-path', '/tmp/tmp_988h6dm']
[2023-11-21T04:58:15.827+0000] {standard_task_runner.py:85} INFO - Job 48: Subtask load_outcome_types_dim
[2023-11-21T04:58:15.902+0000] {task_command.py:416} INFO - Running <TaskInstance: outcomes_dag.load_outcome_types_dim scheduled__2023-11-20T00:00:00+00:00 [running]> on host 921d770aa62c
[2023-11-21T04:58:16.907+0000] {taskinstance.py:1662} INFO - Exporting env vars: AIRFLOW_CTX_DAG_OWNER='***' AIRFLOW_CTX_DAG_ID='outcomes_dag' AIRFLOW_CTX_TASK_ID='load_outcome_types_dim' AIRFLOW_CTX_EXECUTION_DATE='2023-11-20T00:00:00+00:00' AIRFLOW_CTX_TRY_NUMBER='1' AIRFLOW_CTX_DAG_RUN_ID='scheduled__2023-11-20T00:00:00+00:00'
[2023-11-21T04:58:17.144+0000] {logging_mixin.py:154} INFO - dim_outcome_types loaded
[2023-11-21T04:58:17.145+0000] {python.py:194} INFO - Done. Returned value was: None
[2023-11-21T04:58:17.182+0000] {taskinstance.py:1400} INFO - Marking task as SUCCESS. dag_id=outcomes_dag, task_id=load_outcome_types_dim, execution_date=20231120T000000, start_date=20231121T045815, end_date=20231121T045817
[2023-11-21T04:58:17.271+0000] {local_task_job_runner.py:228} INFO - Task exited with return code 0
[2023-11-21T04:58:17.412+0000] {taskinstance.py:2778} INFO - 0 downstream tasks scheduled from follow-on schedule check
