[2023-11-21T04:17:08.305+0000] {taskinstance.py:1159} INFO - Dependencies all met for dep_context=non-requeueable deps ti=<TaskInstance: outcomes_dag.load_outcome_types_dim manual__2023-11-21T04:15:17.438748+00:00 [queued]>
[2023-11-21T04:17:08.349+0000] {taskinstance.py:1159} INFO - Dependencies all met for dep_context=requeueable deps ti=<TaskInstance: outcomes_dag.load_outcome_types_dim manual__2023-11-21T04:15:17.438748+00:00 [queued]>
[2023-11-21T04:17:08.352+0000] {taskinstance.py:1361} INFO - Starting attempt 1 of 1
[2023-11-21T04:17:08.425+0000] {taskinstance.py:1382} INFO - Executing <Task(PythonOperator): load_outcome_types_dim> on 2023-11-21 04:15:17.438748+00:00
[2023-11-21T04:17:08.446+0000] {standard_task_runner.py:57} INFO - Started process 266 to run task
[2023-11-21T04:17:08.473+0000] {standard_task_runner.py:84} INFO - Running: ['***', 'tasks', 'run', 'outcomes_dag', 'load_outcome_types_dim', 'manual__2023-11-21T04:15:17.438748+00:00', '--job-id', '34', '--raw', '--subdir', 'DAGS_FOLDER/outcomes_dag.py', '--cfg-path', '/tmp/tmppaqvg09g']
[2023-11-21T04:17:08.498+0000] {standard_task_runner.py:85} INFO - Job 34: Subtask load_outcome_types_dim
[2023-11-21T04:17:08.642+0000] {task_command.py:416} INFO - Running <TaskInstance: outcomes_dag.load_outcome_types_dim manual__2023-11-21T04:15:17.438748+00:00 [running]> on host dc3ce06c67c1
[2023-11-21T04:17:20.114+0000] {taskinstance.py:1662} INFO - Exporting env vars: AIRFLOW_CTX_DAG_OWNER='***' AIRFLOW_CTX_DAG_ID='outcomes_dag' AIRFLOW_CTX_TASK_ID='load_outcome_types_dim' AIRFLOW_CTX_EXECUTION_DATE='2023-11-21T04:15:17.438748+00:00' AIRFLOW_CTX_TRY_NUMBER='1' AIRFLOW_CTX_DAG_RUN_ID='manual__2023-11-21T04:15:17.438748+00:00'
[2023-11-21T04:17:21.744+0000] {taskinstance.py:1937} ERROR - Task failed with exception
Traceback (most recent call last):
  File "/home/airflow/.local/lib/python3.8/site-packages/sqlalchemy/engine/base.py", line 1910, in _execute_context
    self.dialect.do_execute(
  File "/home/airflow/.local/lib/python3.8/site-packages/sqlalchemy/engine/default.py", line 736, in do_execute
    cursor.execute(statement, parameters)
psycopg2.errors.UndefinedColumn: column "outcome_types_id" does not exist
LINE 1: ...ate', 9), ('N/A', 10), ('Stolen', 11) ON CONFLICT (outcome_t...
                                                             ^
HINT:  Perhaps you meant to reference the column "dim_outcome_types.outcome_type_id".


The above exception was the direct cause of the following exception:

Traceback (most recent call last):
  File "/home/airflow/.local/lib/python3.8/site-packages/airflow/operators/python.py", line 192, in execute
    return_value = self.execute_callable()
  File "/home/airflow/.local/lib/python3.8/site-packages/airflow/operators/python.py", line 209, in execute_callable
    return self.python_callable(*self.op_args, **self.op_kwargs)
  File "/opt/airflow/dags/etl_scripts/load.py", line 20, in load_data
    pd.read_parquet(table_file).to_sql(table_name, conn, if_exists="append", index=False, method = insert_on_conflict_nothing)
  File "/home/airflow/.local/lib/python3.8/site-packages/pandas/core/generic.py", line 2878, in to_sql
    return sql.to_sql(
  File "/home/airflow/.local/lib/python3.8/site-packages/pandas/io/sql.py", line 769, in to_sql
    return pandas_sql.to_sql(
  File "/home/airflow/.local/lib/python3.8/site-packages/pandas/io/sql.py", line 1920, in to_sql
    total_inserted = sql_engine.insert_records(
  File "/home/airflow/.local/lib/python3.8/site-packages/pandas/io/sql.py", line 1470, in insert_records
    raise err
  File "/home/airflow/.local/lib/python3.8/site-packages/pandas/io/sql.py", line 1461, in insert_records
    return table.insert(chunksize=chunksize, method=method)
  File "/home/airflow/.local/lib/python3.8/site-packages/pandas/io/sql.py", line 1023, in insert
    num_inserted = exec_insert(conn, keys, chunk_iter)
  File "/opt/airflow/dags/etl_scripts/load.py", line 17, in insert_on_conflict_nothing
    result = conn.execute(stmt)
  File "/home/airflow/.local/lib/python3.8/site-packages/sqlalchemy/engine/base.py", line 1385, in execute
    return meth(self, multiparams, params, _EMPTY_EXECUTION_OPTS)
  File "/home/airflow/.local/lib/python3.8/site-packages/sqlalchemy/sql/elements.py", line 334, in _execute_on_connection
    return connection._execute_clauseelement(
  File "/home/airflow/.local/lib/python3.8/site-packages/sqlalchemy/engine/base.py", line 1577, in _execute_clauseelement
    ret = self._execute_context(
  File "/home/airflow/.local/lib/python3.8/site-packages/sqlalchemy/engine/base.py", line 1953, in _execute_context
    self._handle_dbapi_exception(
  File "/home/airflow/.local/lib/python3.8/site-packages/sqlalchemy/engine/base.py", line 2134, in _handle_dbapi_exception
    util.raise_(
  File "/home/airflow/.local/lib/python3.8/site-packages/sqlalchemy/util/compat.py", line 211, in raise_
    raise exception
  File "/home/airflow/.local/lib/python3.8/site-packages/sqlalchemy/engine/base.py", line 1910, in _execute_context
    self.dialect.do_execute(
  File "/home/airflow/.local/lib/python3.8/site-packages/sqlalchemy/engine/default.py", line 736, in do_execute
    cursor.execute(statement, parameters)
sqlalchemy.exc.ProgrammingError: (psycopg2.errors.UndefinedColumn) column "outcome_types_id" does not exist
LINE 1: ...ate', 9), ('N/A', 10), ('Stolen', 11) ON CONFLICT (outcome_t...
                                                             ^
HINT:  Perhaps you meant to reference the column "dim_outcome_types.outcome_type_id".

[SQL: INSERT INTO dim_outcome_types (outcome_type, outcome_type_id) VALUES (%(outcome_type_m0)s, %(outcome_type_id_m0)s), (%(outcome_type_m1)s, %(outcome_type_id_m1)s), (%(outcome_type_m2)s, %(outcome_type_id_m2)s), (%(outcome_type_m3)s, %(outcome_type_id_m3)s), (%(outcome_type_m4)s, %(outcome_type_id_m4)s), (%(outcome_type_m5)s, %(outcome_type_id_m5)s), (%(outcome_type_m6)s, %(outcome_type_id_m6)s), (%(outcome_type_m7)s, %(outcome_type_id_m7)s), (%(outcome_type_m8)s, %(outcome_type_id_m8)s), (%(outcome_type_m9)s, %(outcome_type_id_m9)s), (%(outcome_type_m10)s, %(outcome_type_id_m10)s) ON CONFLICT (outcome_types_id) DO NOTHING]
[parameters: {'outcome_type_m0': 'Rto-Adopt', 'outcome_type_id_m0': 1, 'outcome_type_m1': 'Adoption', 'outcome_type_id_m1': 2, 'outcome_type_m2': 'Euthanasia', 'outcome_type_id_m2': 3, 'outcome_type_m3': 'Transfer', 'outcome_type_id_m3': 4, 'outcome_type_m4': 'Return to Owner', 'outcome_type_id_m4': 5, 'outcome_type_m5': 'Died', 'outcome_type_id_m5': 6, 'outcome_type_m6': 'Disposal', 'outcome_type_id_m6': 7, 'outcome_type_m7': 'Missing', 'outcome_type_id_m7': 8, 'outcome_type_m8': 'Relocate', 'outcome_type_id_m8': 9, 'outcome_type_m9': 'N/A', 'outcome_type_id_m9': 10, 'outcome_type_m10': 'Stolen', 'outcome_type_id_m10': 11}]
(Background on this error at: https://sqlalche.me/e/14/f405)
[2023-11-21T04:17:22.389+0000] {taskinstance.py:1400} INFO - Marking task as FAILED. dag_id=outcomes_dag, task_id=load_outcome_types_dim, execution_date=20231121T041517, start_date=20231121T041708, end_date=20231121T041722
[2023-11-21T04:17:22.928+0000] {standard_task_runner.py:104} ERROR - Failed to execute job 34 for task load_outcome_types_dim ((psycopg2.errors.UndefinedColumn) column "outcome_types_id" does not exist
LINE 1: ...ate', 9), ('N/A', 10), ('Stolen', 11) ON CONFLICT (outcome_t...
                                                             ^
HINT:  Perhaps you meant to reference the column "dim_outcome_types.outcome_type_id".

[SQL: INSERT INTO dim_outcome_types (outcome_type, outcome_type_id) VALUES (%(outcome_type_m0)s, %(outcome_type_id_m0)s), (%(outcome_type_m1)s, %(outcome_type_id_m1)s), (%(outcome_type_m2)s, %(outcome_type_id_m2)s), (%(outcome_type_m3)s, %(outcome_type_id_m3)s), (%(outcome_type_m4)s, %(outcome_type_id_m4)s), (%(outcome_type_m5)s, %(outcome_type_id_m5)s), (%(outcome_type_m6)s, %(outcome_type_id_m6)s), (%(outcome_type_m7)s, %(outcome_type_id_m7)s), (%(outcome_type_m8)s, %(outcome_type_id_m8)s), (%(outcome_type_m9)s, %(outcome_type_id_m9)s), (%(outcome_type_m10)s, %(outcome_type_id_m10)s) ON CONFLICT (outcome_types_id) DO NOTHING]
[parameters: {'outcome_type_m0': 'Rto-Adopt', 'outcome_type_id_m0': 1, 'outcome_type_m1': 'Adoption', 'outcome_type_id_m1': 2, 'outcome_type_m2': 'Euthanasia', 'outcome_type_id_m2': 3, 'outcome_type_m3': 'Transfer', 'outcome_type_id_m3': 4, 'outcome_type_m4': 'Return to Owner', 'outcome_type_id_m4': 5, 'outcome_type_m5': 'Died', 'outcome_type_id_m5': 6, 'outcome_type_m6': 'Disposal', 'outcome_type_id_m6': 7, 'outcome_type_m7': 'Missing', 'outcome_type_id_m7': 8, 'outcome_type_m8': 'Relocate', 'outcome_type_id_m8': 9, 'outcome_type_m9': 'N/A', 'outcome_type_id_m9': 10, 'outcome_type_m10': 'Stolen', 'outcome_type_id_m10': 11}]
(Background on this error at: https://sqlalche.me/e/14/f405); 266)
[2023-11-21T04:17:23.180+0000] {local_task_job_runner.py:228} INFO - Task exited with return code 1
[2023-11-21T04:17:24.783+0000] {taskinstance.py:2778} INFO - 0 downstream tasks scheduled from follow-on schedule check
